Workbook

Sheet Перу(январь)
A3: Desk1 - Camila 3 | K3: Desk3 - Corie
A4: Crossgif (перу сейчас) | K4: Crossgif (перу сейчас)
A5: Дата | B5: Общий спенд | C5: Подписки | D5: Диалоги | E5: ФД | F5: Цена подписки | G5: Цена ФД | H5: Конверсия % | I5: ЗП | K5: Дата | L5: Общий спенд(вручную) | M5: Общий спенд | N5: Подписки | O5: Диалоги | P5: ФД | Q5: Цена подписки | R5: Цена ФД | S5: Конверсия % Подписки/Диалоги | T5: ЗП
A6: 46023 | B6: =IFERROR(__xludf.DUMMYFUNCTION("SUM(IMPORTRANGE(""1juk7449zs4jpNuI-o5X7XCsKjbIAXWPjQAMji4MmS2g"", ""1/2026!m5:m9""))"),0.0) -> 0 | C6: 0 | D6: 0 | E6: 1 | F6: =IFERROR(B6/C6, 0) -> 0 | G6: =IFERROR(B6/E6, 0) -> 0 | H6: =IFERROR(D6/C6, 0) -> 0 | I6: =B6*0.12 -> 0 | K6: 46023 | L6: =IFERROR(__xludf.DUMMYFUNCTION("(IMPORTRANGE(""1INH19ghCw782QEanlWDCs5aT59ol_teq6F7nat1cE_0"", ""Январь!b2:b32""))"),"") | M6: =IFERROR(__xludf.DUMMYFUNCTION("SUM(IMPORTRANGE(""1juk7449zs4jpNuI-o5X7XCsKjbIAXWPjQAMji4MmS2g"", ""1/2026!m10:m19""))"),0.0) -> 0 | O6: 6 | P6: 1 | Q6: =IFERROR(M6/N6, 0) -> 0 | R6: =IFERROR(M6/P6, 0) -> 0 | S6: =IFERROR(O6/N6, 0)*100 -> 0 | T6: =M6*0.1 -> 0
A7: 46024 | B7: =IFERROR(__xludf.DUMMYFUNCTION("SUM(IMPORTRANGE(""1juk7449zs4jpNuI-o5X7XCsKjbIAXWPjQAMji4MmS2g"", ""1/2026!n5:n9""))"),0.0) -> 0 | C7: 0 | D7: 1 | E7: 0 | F7: =IFERROR(B7/C7, 0) -> 0 | G7: =IFERROR(B7/E7, 0) -> 0 | H7: =IFERROR(D7/C7, 0) -> 0 | I7: =B7*0.12 -> 0 | K7: 46024 | M7: =IFERROR(__xludf.DUMMYFUNCTION("SUM(IMPORTRANGE(""1juk7449zs4jpNuI-o5X7XCsKjbIAXWPjQAMji4MmS2g"", ""1/2026!n10:n19""))"),0.0) -> 0 | N7: 1 | O7: 3 | P7: 2 | Q7: =IFERROR(M7/N7, 0) -> 0 | R7: =IFERROR(M7/P7, 0) -> 0 | S7: =IFERROR(O7/N7, 0) -> 3 | T7: =M7*0.1 -> 0
A8: 46025 | B8: =IFERROR(__xludf.DUMMYFUNCTION("SUM(IMPORTRANGE(""1juk7449zs4jpNuI-o5X7XCsKjbIAXWPjQAMji4MmS2g"", ""1/2026!o5:p9""))"),0.0) -> 0 | C8: 0 | D8: 0 | E8: 0 | F8: =IFERROR(B8/C8, 0) -> 0 | G8: =IFERROR(B8/E8, 0) -> 0 | H8: =IFERROR(D8/C8, 0) -> 0 | I8: =B8*0.12 -> 0 | K8: 46025 | L8: =IFERROR(__xludf.DUMMYFUNCTION("""COMPUTED_VALUE"""),369.21) -> 369.21 | M8: =IFERROR(__xludf.DUMMYFUNCTION("SUM(IMPORTRANGE(""1juk7449zs4jpNuI-o5X7XCsKjbIAXWPjQAMji4MmS2g"", ""1/2026!o10:o19""))"),368.08) -> 368.08 | N8: 436 | O8: 174 | P8: 6 | Q8: =IFERROR(M8/N8, 0) -> 0.84422018 | R8: =IFERROR(M8/P8, 0) -> 61.346667 | S8: =IFERROR(O8/N8, 0) -> 0.39908257 | T8: =M8*0.1 -> 36.808
A9: 46026 | B9: =IFERROR(__xludf.DUMMYFUNCTION("SUM(IMPORTRANGE(""1juk7449zs4jpNuI-o5X7XCsKjbIAXWPjQAMji4MmS2g"", ""1/2026!q5:q9""))"),0.0) -> 0 | C9: 0 | D9: 2 | E9: 0 | F9: =IFERROR(B9/C9, 0) -> 0 | G9: =IFERROR(B9/E9, 0) -> 0 | H9: =IFERROR(D9/C9, 0) -> 0 | I9: =B9*0.12 -> 0 | K9: 46026 | L9: =IFERROR(__xludf.DUMMYFUNCTION("""COMPUTED_VALUE"""),289.76) -> 289.76 | M9: =IFERROR(__xludf.DUMMYFUNCTION("SUM(IMPORTRANGE(""1juk7449zs4jpNuI-o5X7XCsKjbIAXWPjQAMji4MmS2g"", ""1/2026!p10:p19""))"),291.0) -> 291 | N9: 343 | O9: 145 | P9: 4 | Q9: =IFERROR(M9/N9, 0) -> 0.8483965 | R9: =IFERROR(M9/P9, 0) -> 72.75 | S9: =IFERROR(O9/N9, 0) -> 0.42274052 | T9: =M9*0.1 -> 29.1
A10: 46027 | B10: =IFERROR(__xludf.DUMMYFUNCTION("SUM(IMPORTRANGE(""1juk7449zs4jpNuI-o5X7XCsKjbIAXWPjQAMji4MmS2g"", ""1/2026!r5:r9""))"),0.0) -> 0 | D10: 2 | F10: =IFERROR(B10/C10, 0) -> 0 | G10: =IFERROR(B10/E10, 0) -> 0 | H10: =IFERROR(D10/C10, 0) -> 0 | I10: =B10*0.12 -> 0 | K10: 46027 | L10: =IFERROR(__xludf.DUMMYFUNCTION("""COMPUTED_VALUE"""),327.57) -> 327.57 | M10: =IFERROR(__xludf.DUMMYFUNCTION("SUM(IMPORTRANGE(""1juk7449zs4jpNuI-o5X7XCsKjbIAXWPjQAMji4MmS2g"", ""1/2026!q10:q19""))"),327.55) -> 327.55 | N10: 432 | O10: 207 | P10: 7 | Q10: =IFERROR(M10/N10, 0) -> 0.75821759 | R10: =IFERROR(M10/P10, 0) -> 46.792857 | S10: =IFERROR(O10/N10, 0) -> 0.47916667 | T10: =M10*0.1 -> 32.755
A11: 46028 | B11: 0 | C11: 0 | D11: 2 | E11: 0 | F11: =IFERROR(B11/C11, 0) -> 0 | G11: =IFERROR(B11/E11, 0) -> 0 | H11: =IFERROR(D11/C11, 0) -> 0 | I11: =B11*0.12 -> 0 | K11: 46028 | L11: =IFERROR(__xludf.DUMMYFUNCTION("""COMPUTED_VALUE"""),394.23) -> 394.23 | M11: =IFERROR(__xludf.DUMMYFUNCTION("SUM(IMPORTRANGE(""1juk7449zs4jpNuI-o5X7XCsKjbIAXWPjQAMji4MmS2g"", ""1/2026!r10:r19""))"),393.40000000000003) -> 393.4 | N11: 457 | O11: 222 | P11: 7 | Q11: =IFERROR(M11/N11, 0) -> 0.86083151 | R11: =IFERROR(M11/P11, 0) -> 56.2 | S11: =IFERROR(O11/N11, 0) -> 0.48577681 | T11: =M11*0.1 -> 39.34
A12: 46029 | B12: 0 | C12: 0 | D12: 2 | E12: 0 | F12: =IFERROR(B12/C12, 0) -> 0 | G12: =IFERROR(B12/E12, 0) -> 0 | H12: =IFERROR(D12/C12, 0) -> 0 | I12: =B12*0.12 -> 0 | K12: 46029 | L12: =IFERROR(__xludf.DUMMYFUNCTION("""COMPUTED_VALUE"""),357.8) -> 357.8 | M12: =IFERROR(__xludf.DUMMYFUNCTION("SUM(IMPORTRANGE(""1juk7449zs4jpNuI-o5X7XCsKjbIAXWPjQAMji4MmS2g"", ""1/2026!s10:s19""))"),346.96) -> 346.96 | N12: 362 | O12: 163 | P12: 8 | Q12: =IFERROR(M12/N12, 0) -> 0.95845304 | R12: =IFERROR(M12/P12, 0) -> 43.37 | S12: =IFERROR(O12/N12, 0) -> 0.45027624 | T12: =M12*0.1 -> 34.696
A13: 46030 | F13: =IFERROR(B13/C13, 0) -> 0 | G13: =IFERROR(B13/E13, 0) -> 0 | H13: =IFERROR(D13/C13, 0) -> 0 | I13: =B13*0.12 -> 0 | K13: 46030 | L13: =IFERROR(__xludf.DUMMYFUNCTION("""COMPUTED_VALUE"""),422.03) -> 422.03 | M13: =IFERROR(__xludf.DUMMYFUNCTION("SUM(IMPORTRANGE(""1juk7449zs4jpNuI-o5X7XCsKjbIAXWPjQAMji4MmS2g"", ""1/2026!t10:t19""))"),422.06) -> 422.06 | N13: 364 | O13: 190 | P13: 5 | Q13: =IFERROR(M13/N13, 0) -> 1.1595055 | R13: =IFERROR(M13/P13, 0) -> 84.412 | S13: =IFERROR(O13/N13, 0) -> 0.52197802 | T13: =M13*0.1 -> 42.206
A14: 46031 | F14: =IFERROR(B14/C14, 0) -> 0 | G14: =IFERROR(B14/E14, 0) -> 0 | H14: =IFERROR(D14/C14, 0) -> 0 | I14: =B14*0.12 -> 0 | K14: 46031 | L14: =IFERROR(__xludf.DUMMYFUNCTION("""COMPUTED_VALUE"""),433.24) -> 433.24 | M14: =IFERROR(__xludf.DUMMYFUNCTION("SUM(IMPORTRANGE(""1juk7449zs4jpNuI-o5X7XCsKjbIAXWPjQAMji4MmS2g"", ""1/2026!u10:u19""))"),433.29) -> 433.29 | N14: 386 | O14: 201 | P14: 15 | Q14: =IFERROR(M14/N14, 0) -> 1.122513 | R14: =IFERROR(M14/P14, 0) -> 28.886 | S14: =IFERROR(O14/N14, 0) -> 0.52072539 | T14: =M14*0.1 -> 43.329
A15: 46032 | F15: =IFERROR(B15/C15, 0) -> 0 | G15: =IFERROR(B15/E15, 0) -> 0 | H15: =IFERROR(D15/C15, 0) -> 0 | I15: =B15*0.12 -> 0 | K15: 46032 | L15: =IFERROR(__xludf.DUMMYFUNCTION("""COMPUTED_VALUE"""),505.71) -> 505.71 | M15: =IFERROR(__xludf.DUMMYFUNCTION("SUM(IMPORTRANGE(""1juk7449zs4jpNuI-o5X7XCsKjbIAXWPjQAMji4MmS2g"", ""1/2026!v10:v19""))"),503.57000000000005) -> 503.57 | N15: 361 | O15: 346 | P15: 8 | Q15: =IFERROR(M15/N15, 0) -> 1.3949307 | R15: =IFERROR(M15/P15, 0) -> 62.94625 | S15: =IFERROR(O15/N15, 0) -> 0.95844875 | T15: =M15*0.1 -> 50.357
A16: 46033 | F16: =IFERROR(B16/C16, 0) -> 0 | G16: =IFERROR(B16/E16, 0) -> 0 | H16: =IFERROR(D16/C16, 0) -> 0 | I16: =B16*0.12 -> 0 | K16: 46033 | L16: =IFERROR(__xludf.DUMMYFUNCTION("""COMPUTED_VALUE"""),378.45) -> 378.45 | M16: =IFERROR(__xludf.DUMMYFUNCTION("SUM(IMPORTRANGE(""1juk7449zs4jpNuI-o5X7XCsKjbIAXWPjQAMji4MmS2g"", ""1/2026!w10:w19""))"),378.4100000000001) -> 378.41 | N16: 346 | O16: 178 | P16: 10 | Q16: =IFERROR(M16/N16, 0) -> 1.0936705 | R16: =IFERROR(M16/P16, 0) -> 37.841 | S16: =IFERROR(O16/N16, 0) -> 0.51445087 | T16: =M16*0.1 -> 37.841
A17: 46034 | F17: =IFERROR(B17/C17, 0) -> 0 | G17: =IFERROR(B17/E17, 0) -> 0 | H17: =IFERROR(D17/C17, 0) -> 0 | I17: =B17*0.12 -> 0 | K17: 46034 | L17: =IFERROR(__xludf.DUMMYFUNCTION("""COMPUTED_VALUE"""),452.18) -> 452.18 | M17: =IFERROR(__xludf.DUMMYFUNCTION("SUM(IMPORTRANGE(""1juk7449zs4jpNuI-o5X7XCsKjbIAXWPjQAMji4MmS2g"", ""1/2026!x10:x19""))"),454.23) -> 454.23 | N17: 421 | O17: 186 | P17: 3 | Q17: =IFERROR(M17/N17, 0) -> 1.0789311 | R17: =IFERROR(M17/P17, 0) -> 151.41 | S17: =IFERROR(O17/N17, 0) -> 0.44180523 | T17: =M17*0.1 -> 45.423
A18: 46035 | F18: =IFERROR(B18/C18, 0) -> 0 | G18: =IFERROR(B18/E18, 0) -> 0 | H18: =IFERROR(D18/C18, 0) -> 0 | I18: =B18*0.12 -> 0 | K18: 46035 | L18: =IFERROR(__xludf.DUMMYFUNCTION("""COMPUTED_VALUE"""),452.84) -> 452.84 | M18: =IFERROR(__xludf.DUMMYFUNCTION("SUM(IMPORTRANGE(""1juk7449zs4jpNuI-o5X7XCsKjbIAXWPjQAMji4MmS2g"", ""1/2026!y10:y19""))"),471.80000000000007) -> 471.8 | N18: 159 | O18: 63 | P18: 0 | Q18: =IFERROR(M18/N18, 0) -> 2.9672956 | R18: =IFERROR(M18/P18, 0) -> 0 | S18: =IFERROR(O18/N18, 0) -> 0.39622642 | T18: =M18*0.1 -> 47.18
A19: 46036 | F19: =IFERROR(B19/C19, 0) -> 0 | G19: =IFERROR(B19/E19, 0) -> 0 | H19: =IFERROR(D19/C19, 0) -> 0 | I19: =B19*0.12 -> 0 | K19: 46036 | L19: =IFERROR(__xludf.DUMMYFUNCTION("""COMPUTED_VALUE"""),365.48) -> 365.48 | M19: =IFERROR(__xludf.DUMMYFUNCTION("SUM(IMPORTRANGE(""1juk7449zs4jpNuI-o5X7XCsKjbIAXWPjQAMji4MmS2g"", ""1/2026!z10:z19""))"),379.96) -> 379.96 | N19: 126 | O19: 58 | P19: 3 | Q19: =IFERROR(M19/N19, 0) -> 3.0155556 | R19: =IFERROR(M19/P19, 0) -> 126.65333 | S19: =IFERROR(O19/N19, 0) -> 0.46031746 | T19: =M19*0.1 -> 37.996
A20: 46037 | F20: =IFERROR(B20/C20, 0) -> 0 | G20: =IFERROR(B20/E20, 0) -> 0 | H20: =IFERROR(D20/C20, 0) -> 0 | I20: =B20*0.12 -> 0 | K20: 46037 | L20: =IFERROR(__xludf.DUMMYFUNCTION("""COMPUTED_VALUE"""),409.61) -> 409.61 | M20: =IFERROR(__xludf.DUMMYFUNCTION("SUM(IMPORTRANGE(""1juk7449zs4jpNuI-o5X7XCsKjbIAXWPjQAMji4MmS2g"", ""1/2026!aa10:aa19""))"),409.53000000000003) -> 409.53 | N20: 115 | O20: 61 | P20: 3 | Q20: =IFERROR(M20/N20, 0) -> 3.5611304 | R20: =IFERROR(M20/P20, 0) -> 136.51 | S20: =IFERROR(O20/N20, 0) -> 0.53043478 | T20: =M20*0.1 -> 40.953
A21: 46038 | F21: =IFERROR(B21/C21, 0) -> 0 | G21: =IFERROR(B21/E21, 0) -> 0 | H21: =IFERROR(D21/C21, 0) -> 0 | I21: =B21*0.12 -> 0 | K21: 46038 | L21: =IFERROR(__xludf.DUMMYFUNCTION("""COMPUTED_VALUE"""),459.6) -> 459.6 | M21: =IFERROR(__xludf.DUMMYFUNCTION("SUM(IMPORTRANGE(""1juk7449zs4jpNuI-o5X7XCsKjbIAXWPjQAMji4MmS2g"", ""1/2026!ab10:ab19""))"),399.7) -> 399.7 | N21: 72 | O21: 34 | P21: 4 | Q21: =IFERROR(M21/N21, 0) -> 5.5513889 | R21: =IFERROR(M21/P21, 0) -> 99.925 | S21: =IFERROR(O21/N21, 0) -> 0.47222222 | T21: =M21*0.1 -> 39.97
A22: 46039 | F22: =IFERROR(B22/C22, 0) -> 0 | G22: =IFERROR(B22/E22, 0) -> 0 | H22: =IFERROR(D22/C22, 0) -> 0 | I22: =B22*0.12 -> 0 | K22: 46039 | L22: =IFERROR(__xludf.DUMMYFUNCTION("""COMPUTED_VALUE"""),453.24) -> 453.24 | M22: =IFERROR(__xludf.DUMMYFUNCTION("SUM(IMPORTRANGE(""1juk7449zs4jpNuI-o5X7XCsKjbIAXWPjQAMji4MmS2g"", ""1/2026!ac10:ac19""))"),453.22) -> 453.22 | N22: 219 | O22: 102 | P22: 2 | Q22: =IFERROR(M22/N22, 0) -> 2.0694977 | R22: =IFERROR(M22/P22, 0) -> 226.61 | S22: =IFERROR(O22/N22, 0) -> 0.46575342 | T22: =M22*0.1 -> 45.322
A23: 46040 | F23: =IFERROR(B23/C23, 0) -> 0 | G23: =IFERROR(B23/E23, 0) -> 0 | H23: =IFERROR(D23/C23, 0) -> 0 | I23: =B23*0.12 -> 0 | K23: 46040 | L23: =IFERROR(__xludf.DUMMYFUNCTION("""COMPUTED_VALUE"""),406.69) -> 406.69 | M23: =IFERROR(__xludf.DUMMYFUNCTION("SUM(IMPORTRANGE(""1juk7449zs4jpNuI-o5X7XCsKjbIAXWPjQAMji4MmS2g"", ""1/2026!ad10:ad19""))"),436.0) -> 436 | Q23: =IFERROR(M23/N23, 0) -> 0 | R23: =IFERROR(M23/P23, 0) -> 0 | S23: =IFERROR(O23/N23, 0) -> 0 | T23: =M23*0.1 -> 43.6
A24: 46041 | F24: =IFERROR(B24/C24, 0) -> 0 | G24: =IFERROR(B24/E24, 0) -> 0 | H24: =IFERROR(D24/C24, 0) -> 0 | I24: =B24*0.12 -> 0 | K24: 46041 | L24: =IFERROR(__xludf.DUMMYFUNCTION("""COMPUTED_VALUE"""),405.91) -> 405.91 | M24: =IFERROR(__xludf.DUMMYFUNCTION("SUM(IMPORTRANGE(""1juk7449zs4jpNuI-o5X7XCsKjbIAXWPjQAMji4MmS2g"", ""1/2026!ae10:ae19""))"),397.92) -> 397.92 | Q24: =IFERROR(M24/N24, 0) -> 0 | R24: =IFERROR(M24/P24, 0) -> 0 | S24: =IFERROR(O24/N24, 0) -> 0 | T24: =M24*0.1 -> 39.792
A25: 46042 | F25: =IFERROR(B25/C25, 0) -> 0 | G25: =IFERROR(B25/E25, 0) -> 0 | H25: =IFERROR(D25/C25, 0) -> 0 | I25: =B25*0.12 -> 0 | K25: 46042 | M25: =IFERROR(__xludf.DUMMYFUNCTION("SUM(IMPORTRANGE(""1juk7449zs4jpNuI-o5X7XCsKjbIAXWPjQAMji4MmS2g"", ""1/2026!af10:af19""))"),9.71) -> 9.71 | Q25: =IFERROR(M25/N25, 0) -> 0 | R25: =IFERROR(M25/P25, 0) -> 0 | S25: =IFERROR(O25/N25, 0) -> 0 | T25: =M25*0.1 -> 0.971
A26: 46043 | F26: =IFERROR(B26/C26, 0) -> 0 | G26: =IFERROR(B26/E26, 0) -> 0 | H26: =IFERROR(D26/C26, 0) -> 0 | I26: =B26*0.12 -> 0 | K26: 46043 | M26: =IFERROR(__xludf.DUMMYFUNCTION("SUM(IMPORTRANGE(""1juk7449zs4jpNuI-o5X7XCsKjbIAXWPjQAMji4MmS2g"", ""1/2026!ag10:ag19""))"),0.0) -> 0 | Q26: =IFERROR(M26/N26, 0) -> 0 | R26: =IFERROR(M26/P26, 0) -> 0 | S26: =IFERROR(O26/N26, 0) -> 0 | T26: =M26*0.1 -> 0
A27: 46044 | F27: =IFERROR(B27/C27, 0) -> 0 | G27: =IFERROR(B27/E27, 0) -> 0 | H27: =IFERROR(D27/C27, 0) -> 0 | I27: =B27*0.12 -> 0 | K27: 46044 | M27: =IFERROR(__xludf.DUMMYFUNCTION("SUM(IMPORTRANGE(""1juk7449zs4jpNuI-o5X7XCsKjbIAXWPjQAMji4MmS2g"", ""1/2026!ah10:ah19""))"),0.0) -> 0 | Q27: =IFERROR(M27/N27, 0) -> 0 | R27: =IFERROR(M27/P27, 0) -> 0 | S27: =IFERROR(O27/N27, 0) -> 0 | T27: =M27*0.1 -> 0
A28: 46045 | F28: =IFERROR(B28/C28, 0) -> 0 | G28: =IFERROR(B28/E28, 0) -> 0 | H28: =IFERROR(D28/C28, 0) -> 0 | I28: =B28*0.12 -> 0 | K28: 46045 | M28: =IFERROR(__xludf.DUMMYFUNCTION("SUM(IMPORTRANGE(""1juk7449zs4jpNuI-o5X7XCsKjbIAXWPjQAMji4MmS2g"", ""1/2026!ai10:ai19""))"),0.0) -> 0 | Q28: =IFERROR(M28/N28, 0) -> 0 | R28: =IFERROR(M28/P28, 0) -> 0 | S28: =IFERROR(O28/N28, 0) -> 0 | T28: =M28*0.1 -> 0
A29: 46046 | F29: =IFERROR(B29/C29, 0) -> 0 | G29: =IFERROR(B29/E29, 0) -> 0 | H29: =IFERROR(D29/C29, 0) -> 0 | I29: =B29*0.12 -> 0 | K29: 46046 | M29: =IFERROR(__xludf.DUMMYFUNCTION("SUM(IMPORTRANGE(""1juk7449zs4jpNuI-o5X7XCsKjbIAXWPjQAMji4MmS2g"", ""1/2026!aj10:aj19""))"),0.0) -> 0 | Q29: =IFERROR(M29/N29, 0) -> 0 | R29: =IFERROR(M29/P29, 0) -> 0 | S29: =IFERROR(O29/N29, 0) -> 0 | T29: =M29*0.1 -> 0
A30: 46047 | F30: =IFERROR(B30/C30, 0) -> 0 | G30: =IFERROR(B30/E30, 0) -> 0 | H30: =IFERROR(D30/C30, 0) -> 0 | I30: =B30*0.12 -> 0 | K30: 46047 | M30: =IFERROR(__xludf.DUMMYFUNCTION("SUM(IMPORTRANGE(""1juk7449zs4jpNuI-o5X7XCsKjbIAXWPjQAMji4MmS2g"", ""1/2026!ak10:ak19""))"),0.0) -> 0 | Q30: =IFERROR(M30/N30, 0) -> 0 | R30: =IFERROR(M30/P30, 0) -> 0 | S30: =IFERROR(O30/N30, 0) -> 0 | T30: =M30*0.1 -> 0
A31: 46048 | F31: =IFERROR(B31/C31, 0) -> 0 | G31: =IFERROR(B31/E31, 0) -> 0 | H31: =IFERROR(D31/C31, 0) -> 0 | I31: =B31*0.12 -> 0 | K31: 46048 | M31: =IFERROR(__xludf.DUMMYFUNCTION("SUM(IMPORTRANGE(""1juk7449zs4jpNuI-o5X7XCsKjbIAXWPjQAMji4MmS2g"", ""1/2026!al10:al19""))"),0.0) -> 0 | Q31: =IFERROR(M31/N31, 0) -> 0 | R31: =IFERROR(M31/P31, 0) -> 0 | S31: =IFERROR(O31/N31, 0) -> 0 | T31: =M31*0.1 -> 0
A32: 46049 | F32: =IFERROR(B32/C32, 0) -> 0 | G32: =IFERROR(B32/E32, 0) -> 0 | H32: =IFERROR(D32/C32, 0) -> 0 | I32: =B32*0.12 -> 0 | K32: 46049 | M32: =IFERROR(__xludf.DUMMYFUNCTION("SUM(IMPORTRANGE(""1juk7449zs4jpNuI-o5X7XCsKjbIAXWPjQAMji4MmS2g"", ""1/2026!am10:am19""))"),0.0) -> 0 | Q32: =IFERROR(M32/N32, 0) -> 0 | R32: =IFERROR(M32/P32, 0) -> 0 | S32: =IFERROR(O32/N32, 0) -> 0 | T32: =M32*0.1 -> 0
A33: 46050 | F33: =IFERROR(B33/C33, 0) -> 0 | G33: =IFERROR(B33/E33, 0) -> 0 | H33: =IFERROR(D33/C33, 0) -> 0 | I33: =B33*0.12 -> 0 | K33: 46050 | M33: =IFERROR(__xludf.DUMMYFUNCTION("SUM(IMPORTRANGE(""1juk7449zs4jpNuI-o5X7XCsKjbIAXWPjQAMji4MmS2g"", ""1/2026!an10:an19""))"),0.0) -> 0 | Q33: =IFERROR(M33/N33, 0) -> 0 | R33: =IFERROR(M33/P33, 0) -> 0 | S33: =IFERROR(O33/N33, 0) -> 0 | T33: =M33*0.1 -> 0
A34: 46051 | F34: =IFERROR(B34/C34, 0) -> 0 | G34: =IFERROR(B34/E34, 0) -> 0 | H34: =IFERROR(D34/C34, 0) -> 0 | I34: =B34*0.12 -> 0 | K34: 46051 | M34: =IFERROR(__xludf.DUMMYFUNCTION("SUM(IMPORTRANGE(""1juk7449zs4jpNuI-o5X7XCsKjbIAXWPjQAMji4MmS2g"", ""1/2026!ao10:ao19""))"),0.0) -> 0 | Q34: =IFERROR(M34/N34, 0) -> 0 | R34: =IFERROR(M34/P34, 0) -> 0 | S34: =IFERROR(O34/N34, 0) -> 0 | T34: =M34*0.1 -> 0
A35: 46052 | B35: =IFERROR(__xludf.DUMMYFUNCTION("SUM(IMPORTRANGE(""1juk7449zs4jpNuI-o5X7XCsKjbIAXWPjQAMji4MmS2g"", ""12/2025!ap5:ap12""))"),0.0) -> 0 | F35: =IFERROR(B35/C35, 0) -> 0 | G35: =IFERROR(B35/E35, 0) -> 0 | H35: =IFERROR(D35/C35, 0) -> 0 | I35: =B35*0.12 -> 0 | K35: 46052 | M35: =IFERROR(__xludf.DUMMYFUNCTION("SUM(IMPORTRANGE(""1juk7449zs4jpNuI-o5X7XCsKjbIAXWPjQAMji4MmS2g"", ""1/2026!ap10:ap19""))"),0.0) -> 0 | Q35: =IFERROR(M35/N35, 0) -> 0 | R35: =IFERROR(M35/P35, 0) -> 0 | S35: =IFERROR(O35/N35, 0) -> 0 | T35: =M35*0.1 -> 0
A36: 46053 | B36: =IFERROR(__xludf.DUMMYFUNCTION("SUM(IMPORTRANGE(""1juk7449zs4jpNuI-o5X7XCsKjbIAXWPjQAMji4MmS2g"", ""12/2025!aq5:aq12""))"),0.0) -> 0 | F36: =IFERROR(B36/C36, 0) -> 0 | G36: =IFERROR(B36/E36, 0) -> 0 | H36: =IFERROR(D36/C36, 0) -> 0 | I36: =B36*0.12 -> 0 | K36: 46053 | M36: =IFERROR(__xludf.DUMMYFUNCTION("SUM(IMPORTRANGE(""1juk7449zs4jpNuI-o5X7XCsKjbIAXWPjQAMji4MmS2g"", ""1/2026!aq10:aq19""))"),0.0) -> 0 | Q36: =IFERROR(M36/N36, 0) -> 0 | R36: =IFERROR(M36/P36, 0) -> 0 | S36: =IFERROR(O36/N36, 0) -> 0 | T36: =M36*0.1 -> 0
A37: ИТОГО: | B37: =SUM(B6:B35) -> 0 | C37: =SUM(C6:C35) -> 0 | D37: =SUM(D6:D35) -> 9 | E37: =SUM(E6:E35) -> 1 | F37: =IFERROR(B37/C37, 0) -> 0 | G37: =IFERROR(B37/E37, 0) -> 0 | H37: =IFERROR(D37/C37, 0) -> 0 | I37: =B37*0.12 -> 0 | K37: ИТОГО: | M37: =SUM(M6:M35) -> 6876.39 | N37: =SUM(N6:N36) -> 4600 | O37: =SUM(O6:O36) -> 2339 | P37: =SUM(P6:P36) -> 88 | Q37: =IFERROR(M37/N37, 0) -> 1.4948674 | R37: =IFERROR(M37/P37, 0) -> 78.140795 | S37: =IFERROR(O37/N37, 0) -> 0.50847826 | T37: =M37*0.1 -> 687.639

Sheet Аргентина(январь)
A3: Desk1 - Camila 3
A4: Crossgif (перу сейчас)
A5: Дата | B5: Общий спенд(вручную) | C5: Общий спенд | D5: Подписки | E5: Диалоги | F5: ФД | G5: Цена подписки | H5: Цена ФД | I5: Конверсия % | J5: ЗП
A6: 46023 | B6: =IFERROR(__xludf.DUMMYFUNCTION("(IMPORTRANGE(""1INH19ghCw782QEanlWDCs5aT59ol_teq6F7nat1cE_0"", ""Январь(Аргентина)!b2:b32""))"),"") | G6: =IFERROR(C6/D6, 0) -> 0 | H6: =IFERROR(C6/F6, 0) -> 0 | I6: =IFERROR(E6/D6, 0) -> 0 | J6: =C6*0.1 -> 0
A7: 46024 | G7: =IFERROR(C7/D7, 0) -> 0 | H7: =IFERROR(C7/F7, 0) -> 0 | I7: =IFERROR(E7/D7, 0) -> 0 | J7: =C7*0.1 -> 0
A8: 46025 | G8: =IFERROR(C8/D8, 0) -> 0 | H8: =IFERROR(C8/F8, 0) -> 0 | I8: =IFERROR(E8/D8, 0) -> 0 | J8: =C8*0.1 -> 0
A9: 46026 | G9: =IFERROR(C9/D9, 0) -> 0 | H9: =IFERROR(C9/F9, 0) -> 0 | I9: =IFERROR(E9/D9, 0) -> 0 | J9: =C9*0.1 -> 0
A10: 46027 | G10: =IFERROR(C10/D10, 0) -> 0 | H10: =IFERROR(C10/F10, 0) -> 0 | I10: =IFERROR(E10/D10, 0) -> 0 | J10: =C10*0.1 -> 0
A11: 46028 | G11: =IFERROR(C11/D11, 0) -> 0 | H11: =IFERROR(C11/F11, 0) -> 0 | I11: =IFERROR(E11/D11, 0) -> 0 | J11: =C11*0.1 -> 0
A12: 46029 | G12: =IFERROR(C12/D12, 0) -> 0 | H12: =IFERROR(C12/F12, 0) -> 0 | I12: =IFERROR(E12/D12, 0) -> 0 | J12: =C12*0.1 -> 0
A13: 46030 | G13: =IFERROR(C13/D13, 0) -> 0 | H13: =IFERROR(C13/F13, 0) -> 0 | I13: =IFERROR(E13/D13, 0) -> 0 | J13: =C13*0.1 -> 0
A14: 46031 | G14: =IFERROR(C14/D14, 0) -> 0 | H14: =IFERROR(C14/F14, 0) -> 0 | I14: =IFERROR(E14/D14, 0) -> 0 | J14: =C14*0.1 -> 0
A15: 46032 | G15: =IFERROR(C15/D15, 0) -> 0 | H15: =IFERROR(C15/F15, 0) -> 0 | I15: =IFERROR(E15/D15, 0) -> 0 | J15: =C15*0.1 -> 0
A16: 46033 | G16: =IFERROR(C16/D16, 0) -> 0 | H16: =IFERROR(C16/F16, 0) -> 0 | I16: =IFERROR(E16/D16, 0) -> 0 | J16: =C16*0.1 -> 0
A17: 46034 | G17: =IFERROR(C17/D17, 0) -> 0 | H17: =IFERROR(C17/F17, 0) -> 0 | I17: =IFERROR(E17/D17, 0) -> 0 | J17: =C17*0.1 -> 0
A18: 46035 | G18: =IFERROR(C18/D18, 0) -> 0 | H18: =IFERROR(C18/F18, 0) -> 0 | I18: =IFERROR(E18/D18, 0) -> 0 | J18: =C18*0.1 -> 0
A19: 46036 | G19: =IFERROR(C19/D19, 0) -> 0 | H19: =IFERROR(C19/F19, 0) -> 0 | I19: =IFERROR(E19/D19, 0) -> 0 | J19: =C19*0.1 -> 0
A20: 46037 | B20: =IFERROR(__xludf.DUMMYFUNCTION("""COMPUTED_VALUE"""),105.5) -> 105.5 | C20: =IFERROR(__xludf.DUMMYFUNCTION("SUM(IMPORTRANGE( ""1juk7449zs4jpNuI-o5X7XCsKjbIAXWPjQAMji4MmS2g"", ""1/2026!AA5:AA9"" ))"),105.13) -> 105.13 | D20: 78 | E20: 30 | F20: 0 | G20: =IFERROR(C20/D20, 0) -> 1.3478205 | H20: =IFERROR(C20/F20, 0) -> 0 | I20: =IFERROR(E20/D20, 0) -> 0.38461538 | J20: =C20*0.1 -> 10.513
A21: 46038 | B21: =IFERROR(__xludf.DUMMYFUNCTION("""COMPUTED_VALUE"""),102.05) -> 102.05 | C21: =IFERROR(__xludf.DUMMYFUNCTION("SUM(IMPORTRANGE( ""1juk7449zs4jpNuI-o5X7XCsKjbIAXWPjQAMji4MmS2g"", ""1/2026!Ab5:Ab9"" ))"),95.06) -> 95.06 | D21: 83 | E21: 36 | F21: 0 | G21: =IFERROR(C21/D21, 0) -> 1.1453012 | H21: =IFERROR(C21/F21, 0) -> 0 | I21: =IFERROR(E21/D21, 0) -> 0.43373494 | J21: =C21*0.1 -> 9.506
A22: 46039 | B22: =IFERROR(__xludf.DUMMYFUNCTION("""COMPUTED_VALUE"""),139.2) -> 139.2 | C22: =IFERROR(__xludf.DUMMYFUNCTION("SUM(IMPORTRANGE( ""1juk7449zs4jpNuI-o5X7XCsKjbIAXWPjQAMji4MmS2g"", ""1/2026!Ac5:Ac9"" ))"),139.2) -> 139.2 | D22: 76 | E22: 25 | F22: 1 | G22: =IFERROR(C22/D22, 0) -> 1.8315789 | H22: =IFERROR(C22/F22, 0) -> 139.2 | I22: =IFERROR(E22/D22, 0) -> 0.32894737 | J22: =C22*0.1 -> 13.92
A23: 46040 | B23: =IFERROR(__xludf.DUMMYFUNCTION("""COMPUTED_VALUE"""),119.88) -> 119.88 | G23: =IFERROR(C23/D23, 0) -> 0 | H23: =IFERROR(C23/F23, 0) -> 0 | I23: =IFERROR(E23/D23, 0) -> 0 | J23: =C23*0.1 -> 0
A24: 46041 | B24: =IFERROR(__xludf.DUMMYFUNCTION("""COMPUTED_VALUE"""),109.58) -> 109.58 | G24: =IFERROR(C24/D24, 0) -> 0 | H24: =IFERROR(C24/F24, 0) -> 0 | I24: =IFERROR(E24/D24, 0) -> 0 | J24: =C24*0.1 -> 0
A25: 46042 | G25: =IFERROR(C25/D25, 0) -> 0 | H25: =IFERROR(C25/F25, 0) -> 0 | I25: =IFERROR(E25/D25, 0) -> 0 | J25: =C25*0.1 -> 0
A26: 46043 | G26: =IFERROR(C26/D26, 0) -> 0 | H26: =IFERROR(C26/F26, 0) -> 0 | I26: =IFERROR(E26/D26, 0) -> 0 | J26: =C26*0.1 -> 0
A27: 46044 | G27: =IFERROR(C27/D27, 0) -> 0 | H27: =IFERROR(C27/F27, 0) -> 0 | I27: =IFERROR(E27/D27, 0) -> 0 | J27: =C27*0.1 -> 0
A28: 46045 | G28: =IFERROR(C28/D28, 0) -> 0 | H28: =IFERROR(C28/F28, 0) -> 0 | I28: =IFERROR(E28/D28, 0) -> 0 | J28: =C28*0.1 -> 0
A29: 46046 | G29: =IFERROR(C29/D29, 0) -> 0 | H29: =IFERROR(C29/F29, 0) -> 0 | I29: =IFERROR(E29/D29, 0) -> 0 | J29: =C29*0.1 -> 0
A30: 46047 | G30: =IFERROR(C30/D30, 0) -> 0 | H30: =IFERROR(C30/F30, 0) -> 0 | I30: =IFERROR(E30/D30, 0) -> 0 | J30: =C30*0.1 -> 0
A31: 46048 | G31: =IFERROR(C31/D31, 0) -> 0 | H31: =IFERROR(C31/F31, 0) -> 0 | I31: =IFERROR(E31/D31, 0) -> 0 | J31: =C31*0.1 -> 0
A32: 46049 | G32: =IFERROR(C32/D32, 0) -> 0 | H32: =IFERROR(C32/F32, 0) -> 0 | I32: =IFERROR(E32/D32, 0) -> 0 | J32: =C32*0.1 -> 0
A33: 46050 | G33: =IFERROR(C33/D33, 0) -> 0 | H33: =IFERROR(C33/F33, 0) -> 0 | I33: =IFERROR(E33/D33, 0) -> 0 | J33: =C33*0.1 -> 0
A34: 46051 | G34: =IFERROR(C34/D34, 0) -> 0 | H34: =IFERROR(C34/F34, 0) -> 0 | I34: =IFERROR(E34/D34, 0) -> 0 | J34: =C34*0.1 -> 0
A35: 46052 | G35: =IFERROR(C35/D35, 0) -> 0 | H35: =IFERROR(C35/F35, 0) -> 0 | I35: =IFERROR(E35/D35, 0) -> 0 | J35: =C35*0.1 -> 0
A36: 46053 | G36: =IFERROR(C36/D36, 0) -> 0 | H36: =IFERROR(C36/F36, 0) -> 0 | I36: =IFERROR(E36/D36, 0) -> 0 | J36: =C36*0.1 -> 0
A37: ИТОГО: | C37: =SUM(C6:C35) -> 339.39 | D37: =SUM(D6:D35) -> 237 | E37: =SUM(E6:E35) -> 91 | F37: =SUM(F6:F35) -> 1 | G37: =IFERROR(C37/D37, 0) -> 1.4320253 | H37: =IFERROR(C37/F37, 0) -> 339.39 | I37: =IFERROR(E37/D37, 0) -> 0.38396624 | J37: =C37*0.1 -> 33.939

Sheet Италия(январь)
A3: Cabrera (итальянец)
A4: 759443220489882
A5: Дата | B5: Общий спенд(вручную) | C5: Общий спенд | D5: Подписки | E5: Диалоги | F5: ФД | G5: Цена подписки | H5: Цена ФД | I5: Конверсия % | J5: ЗП | M5: =IFERROR(__xludf.DUMMYFUNCTION("ARRAYFORMULA( IFERROR( TRANSPOSE( IMPORTRANGE( ""1mLYr0R01Ye8tWsFhsIUhEyEhRjCr_h41JpFqzhMvE"", ""DailySpend_jan26!H1:AL1"" ) ), ) ) "),"")
A6: 46023 | B6: =IFERROR(__xludf.DUMMYFUNCTION("(IMPORTRANGE(""1eN5_hhUyg32yZHyoxUmLR3POg4pgiTVa-kjw1DYuCV8"", ""Январь!b2:b32""))"),"") | C6: =IFERROR(__xludf.DUMMYFUNCTION("TRANSPOSE(IMPORTRANGE(""1mLYrOR0lYe8tWsFhslUhEyhEhRjCr_h4lljPfqzhMvE"", ""DailySpend_jan26!h1:al1"")) "),0.0) -> 0 | D6: 0 | E6: 1 | F6: 0 | G6: =IFERROR(C6/D6, 0) -> 0 | H6: =IFERROR(C6/F6, 0) -> 0 | I6: =IFERROR(E6/D6, 0) -> 0 | J6: =C6*0.1 -> 0
A7: 46024 | C7: =IFERROR(__xludf.DUMMYFUNCTION("""COMPUTED_VALUE"""),0.0) -> 0 | D7: 0 | E7: 1 | F7: 0 | G7: =IFERROR(C7/D7, 0) -> 0 | H7: =IFERROR(C7/F7, 0) -> 0 | I7: =IFERROR(E7/D7, 0) -> 0 | J7: =C7*0.1 -> 0
A8: 46025 | C8: =IFERROR(__xludf.DUMMYFUNCTION("""COMPUTED_VALUE"""),0.0) -> 0 | D8: 2 | E8: 0 | F8: 0 | G8: =IFERROR(C8/D8, 0) -> 0 | H8: =IFERROR(C8/F8, 0) -> 0 | I8: =IFERROR(E8/D8, 0) -> 0 | J8: =C8*0.1 -> 0
A9: 46026 | B9: =IFERROR(__xludf.DUMMYFUNCTION("""COMPUTED_VALUE"""),83.13) -> 83.13 | C9: =IFERROR(__xludf.DUMMYFUNCTION("""COMPUTED_VALUE"""),83.13) -> 83.13 | D9: 38 | E9: 23 | F9: 0 | G9: =IFERROR(C9/D9, 0) -> 2.1876316 | H9: =IFERROR(C9/F9, 0) -> 0 | I9: =IFERROR(E9/D9, 0) -> 0.60526316 | J9: =C9*0.1 -> 8.313
A10: 46027 | B10: =IFERROR(__xludf.DUMMYFUNCTION("""COMPUTED_VALUE"""),96.18) -> 96.18 | C10: =IFERROR(__xludf.DUMMYFUNCTION("""COMPUTED_VALUE"""),96.18) -> 96.18 | D10: 37 | E10: 23 | F10: 0 | G10: =IFERROR(C10/D10, 0) -> 2.5994595 | H10: =IFERROR(C10/F10, 0) -> 0 | I10: =IFERROR(E10/D10, 0) -> 0.62162162 | J10: =C10*0.1 -> 9.618
A11: 46028 | B11: =IFERROR(__xludf.DUMMYFUNCTION("""COMPUTED_VALUE"""),169.94) -> 169.94 | C11: =IFERROR(__xludf.DUMMYFUNCTION("""COMPUTED_VALUE"""),169.95999999999998) -> 169.96 | D11: 21 | E11: 9 | F11: 2 | G11: =IFERROR(C11/D11, 0) -> 8.0933333 | H11: =IFERROR(C11/F11, 0) -> 84.98 | I11: =IFERROR(E11/D11, 0) -> 0.42857143 | J11: =C11*0.1 -> 16.996
A12: 46029 | C12: =IFERROR(__xludf.DUMMYFUNCTION("""COMPUTED_VALUE"""),213.38) -> 213.38 | D12: 70 | E12: 41 | F12: 0 | G12: =IFERROR(C12/D12, 0) -> 3.0482857 | H12: =IFERROR(C12/F12, 0) -> 0 | I12: =IFERROR(E12/D12, 0) -> 0.58571429 | J12: =C12*0.1 -> 21.338
A13: 46030 | C13: =IFERROR(__xludf.DUMMYFUNCTION("""COMPUTED_VALUE"""),126.47) -> 126.47 | D13: 33 | E13: 16 | F13: 0 | G13: =IFERROR(C13/D13, 0) -> 3.8324242 | H13: =IFERROR(C13/F13, 0) -> 0 | I13: =IFERROR(E13/D13, 0) -> 0.48484848 | J13: =C13*0.1 -> 12.647
A14: 46031 | C14: =IFERROR(__xludf.DUMMYFUNCTION("""COMPUTED_VALUE"""),240.58) -> 240.58 | D14: 26 | E14: 13 | F14: 0 | G14: =IFERROR(C14/D14, 0) -> 9.2530769 | H14: =IFERROR(C14/F14, 0) -> 0 | I14: =IFERROR(E14/D14, 0) -> 0.5 | J14: =C14*0.1 -> 24.058
A15: 46032 | C15: =IFERROR(__xludf.DUMMYFUNCTION("""COMPUTED_VALUE"""),358.95) -> 358.95 | D15: 107 | E15: 48 | F15: 0 | G15: =IFERROR(C15/D15, 0) -> 3.3546729 | H15: =IFERROR(C15/F15, 0) -> 0 | I15: =IFERROR(E15/D15, 0) -> 0.44859813 | J15: =C15*0.1 -> 35.895
A16: 46033 | C16: =IFERROR(__xludf.DUMMYFUNCTION("""COMPUTED_VALUE"""),83.6) -> 83.6 | D16: 13 | E16: 10 | F16: 2 | G16: =IFERROR(C16/D16, 0) -> 6.4307692 | H16: =IFERROR(C16/F16, 0) -> 41.8 | I16: =IFERROR(E16/D16, 0) -> 0.76923077 | J16: =C16*0.1 -> 8.36
A17: 46034 | C17: =IFERROR(__xludf.DUMMYFUNCTION("""COMPUTED_VALUE"""),70.89) -> 70.89 | D17: 6 | E17: 7 | F17: 2 | G17: =IFERROR(C17/D17, 0) -> 11.815 | H17: =IFERROR(C17/F17, 0) -> 35.445 | I17: =IFERROR(E17/D17, 0) -> 1.1666667 | J17: =C17*0.1 -> 7.089
A18: 46035 | C18: =IFERROR(__xludf.DUMMYFUNCTION("""COMPUTED_VALUE"""),232.46) -> 232.46 | D18: 37 | E18: 26 | F18: 0 | G18: =IFERROR(C18/D18, 0) -> 6.2827027 | H18: =IFERROR(C18/F18, 0) -> 0 | I18: =IFERROR(E18/D18, 0) -> 0.7027027 | J18: =C18*0.1 -> 23.246
A19: 46036 | C19: =IFERROR(__xludf.DUMMYFUNCTION("""COMPUTED_VALUE"""),81.42) -> 81.42 | D19: 9 | E19: 7 | F19: 1 | G19: =IFERROR(C19/D19, 0) -> 9.0466667 | H19: =IFERROR(C19/F19, 0) -> 81.42 | I19: =IFERROR(E19/D19, 0) -> 0.77777778 | J19: =C19*0.1 -> 8.142
A20: 46037 | C20: =IFERROR(__xludf.DUMMYFUNCTION("""COMPUTED_VALUE"""),152.08) -> 152.08 | D20: 21 | E20: 14 | F20: 2 | G20: =IFERROR(C20/D20, 0) -> 7.2419048 | H20: =IFERROR(C20/F20, 0) -> 76.04 | I20: =IFERROR(E20/D20, 0) -> 0.66666667 | J20: =C20*0.1 -> 15.208
A21: 46038 | C21: =IFERROR(__xludf.DUMMYFUNCTION("""COMPUTED_VALUE"""),204.26) -> 204.26 | D21: 48 | E21: 22 | F21: 3 | G21: =IFERROR(C21/D21, 0) -> 4.2554167 | H21: =IFERROR(C21/F21, 0) -> 68.086667 | I21: =IFERROR(E21/D21, 0) -> 0.45833333 | J21: =C21*0.1 -> 20.426
A22: 46039 | C22: =IFERROR(__xludf.DUMMYFUNCTION("""COMPUTED_VALUE"""),202.42) -> 202.42 | D22: 44 | E22: 26 | F22: 2 | G22: =IFERROR(C22/D22, 0) -> 4.6004545 | H22: =IFERROR(C22/F22, 0) -> 101.21 | I22: =IFERROR(E22/D22, 0) -> 0.59090909 | J22: =C22*0.1 -> 20.242
A23: 46040 | C23: =IFERROR(__xludf.DUMMYFUNCTION("""COMPUTED_VALUE"""),142.76) -> 142.76 | G23: =IFERROR(C23/D23, 0) -> 0 | H23: =IFERROR(C23/F23, 0) -> 0 | I23: =IFERROR(E23/D23, 0) -> 0 | J23: =C23*0.1 -> 14.276
A24: 46041 | C24: =IFERROR(__xludf.DUMMYFUNCTION("""COMPUTED_VALUE"""),113.42) -> 113.42 | G24: =IFERROR(C24/D24, 0) -> 0 | H24: =IFERROR(C24/F24, 0) -> 0 | I24: =IFERROR(E24/D24, 0) -> 0 | J24: =C24*0.1 -> 11.342
A25: 46042 | C25: =IFERROR(__xludf.DUMMYFUNCTION("""COMPUTED_VALUE"""),80.52) -> 80.52 | G25: =IFERROR(C25/D25, 0) -> 0 | H25: =IFERROR(C25/F25, 0) -> 0 | I25: =IFERROR(E25/D25, 0) -> 0 | J25: =C25*0.1 -> 8.052
A26: 46043 | C26: =IFERROR(__xludf.DUMMYFUNCTION("""COMPUTED_VALUE"""),0.0) -> 0 | G26: =IFERROR(C26/D26, 0) -> 0 | H26: =IFERROR(C26/F26, 0) -> 0 | I26: =IFERROR(E26/D26, 0) -> 0 | J26: =C26*0.1 -> 0
A27: 46044 | C27: =IFERROR(__xludf.DUMMYFUNCTION("""COMPUTED_VALUE"""),0.0) -> 0 | G27: =IFERROR(C27/D27, 0) -> 0 | H27: =IFERROR(C27/F27, 0) -> 0 | I27: =IFERROR(E27/D27, 0) -> 0 | J27: =C27*0.1 -> 0
A28: 46045 | C28: =IFERROR(__xludf.DUMMYFUNCTION("""COMPUTED_VALUE"""),0.0) -> 0 | G28: =IFERROR(C28/D28, 0) -> 0 | H28: =IFERROR(C28/F28, 0) -> 0 | I28: =IFERROR(E28/D28, 0) -> 0 | J28: =C28*0.1 -> 0
A29: 46046 | C29: =IFERROR(__xludf.DUMMYFUNCTION("""COMPUTED_VALUE"""),0.0) -> 0 | G29: =IFERROR(C29/D29, 0) -> 0 | H29: =IFERROR(C29/F29, 0) -> 0 | I29: =IFERROR(E29/D29, 0) -> 0 | J29: =C29*0.1 -> 0
A30: 46047 | C30: =IFERROR(__xludf.DUMMYFUNCTION("""COMPUTED_VALUE"""),0.0) -> 0 | G30: =IFERROR(C30/D30, 0) -> 0 | H30: =IFERROR(C30/F30, 0) -> 0 | I30: =IFERROR(E30/D30, 0) -> 0 | J30: =C30*0.1 -> 0
A31: 46048 | C31: =IFERROR(__xludf.DUMMYFUNCTION("""COMPUTED_VALUE"""),0.0) -> 0 | G31: =IFERROR(C31/D31, 0) -> 0 | H31: =IFERROR(C31/F31, 0) -> 0 | I31: =IFERROR(E31/D31, 0) -> 0 | J31: =C31*0.1 -> 0
A32: 46049 | C32: =IFERROR(__xludf.DUMMYFUNCTION("""COMPUTED_VALUE"""),0.0) -> 0 | G32: =IFERROR(C32/D32, 0) -> 0 | H32: =IFERROR(C32/F32, 0) -> 0 | I32: =IFERROR(E32/D32, 0) -> 0 | J32: =C32*0.1 -> 0
A33: 46050 | C33: =IFERROR(__xludf.DUMMYFUNCTION("""COMPUTED_VALUE"""),0.0) -> 0 | G33: =IFERROR(C33/D33, 0) -> 0 | H33: =IFERROR(C33/F33, 0) -> 0 | I33: =IFERROR(E33/D33, 0) -> 0 | J33: =C33*0.1 -> 0
A34: 46051 | C34: =IFERROR(__xludf.DUMMYFUNCTION("""COMPUTED_VALUE"""),0.0) -> 0 | G34: =IFERROR(C34/D34, 0) -> 0 | H34: =IFERROR(C34/F34, 0) -> 0 | I34: =IFERROR(E34/D34, 0) -> 0 | J34: =C34*0.1 -> 0
A35: 46052 | C35: =IFERROR(__xludf.DUMMYFUNCTION("""COMPUTED_VALUE"""),0.0) -> 0 | G35: =IFERROR(C35/D35, 0) -> 0 | H35: =IFERROR(C35/F35, 0) -> 0 | I35: =IFERROR(E35/D35, 0) -> 0 | J35: =C35*0.1 -> 0
A36: 46053 | C36: =IFERROR(__xludf.DUMMYFUNCTION("""COMPUTED_VALUE"""),0.0) -> 0 | G36: =IFERROR(C36/D36, 0) -> 0 | H36: =IFERROR(C36/F36, 0) -> 0 | I36: =IFERROR(E36/D36, 0) -> 0 | J36: =C36*0.1 -> 0
A37: ИТОГО: | C37: =SUM(C6:C35) -> 2652.48 | D37: =SUM(D6:D35) -> 512 | E37: =SUM(E6:E35) -> 287 | F37: =SUM(F6:F35) -> 14 | G37: =IFERROR(C37/D37, 0) -> 5.180625 | H37: =IFERROR(C37/F37, 0) -> 189.46286 | I37: =IFERROR(E37/D37, 0) -> 0.56054688 | J37: =C37*0.1 -> 265.248

Sheet Перу(декабрь)
A3: Desk1 - Camila 3 | K3: Desk3 - Corie | U3: Desk1 - основной | AC3: Desk5 - torres | AK3: Desk6 - Dirty
A4: Crossgif (перу сейчас) | K4: Crossgif (перу сейчас) | U4: Crossgif (перу сейчас) | AC4: Crossgif (перу сейчас) | AK4: Crossgif (перу сейчас)
A5: Дата | B5: Общий спенд | C5: Подписки | D5: Диалоги | E5: ФД | F5: Цена подписки | G5: Цена ФД | H5: Конверсия % | I5: ЗП | K5: Дата | L5: Общий спенд | M5: Подписки | N5: Диалоги | O5: ФД | P5: Цена подписки | Q5: Цена ФД | R5: Конверсия % Подписки/Диалоги | S5: ЗП | U5: Дата | V5: Общий спенд | W5: Подписки | X5: Диалоги | Y5: ФД | Z5: Цена подписки | AA5: Конверсия % | AC5: Дата | AD5: Общий спенд | AE5: Подписки | AF5: Диалоги | AG5: ФД | AH5: Цена подписки | AI5: Конверсия % | AK5: Дата | AL5: Общий спенд | AM5: Подписки | AN5: Диалоги | AO5: ФД | AP5: Цена подписки | AQ5: Конверсия %
A6: 45992 | B6: 305.58 | C6: 96 | D6: 46 | E6: 6 | F6: =B6/C6 -> 3.183125 | G6: =B6/E6 -> 50.93 | H6: =D6/C6*100 -> 47.916667 | I6: =B6*0.12 -> 36.6696 | K6: 45992 | L6: =152.98+15.57+82.88 -> 251.43 | M6: 81 | N6: 41 | O6: 4 | P6: =L6/M6 -> 3.1040741 | Q6: =L6/O6 -> 62.8575 | R6: =N6/M6*100 -> 50.617284 | S6: =L6*0.1 -> 25.143 | U6: 45962 | AC6: 45962 | AK6: 45962
A7: 45993 | B7: 296.7 | C7: 92 | D7: 41 | E7: 1 | F7: =B7/C7 -> 3.225 | G7: =B7/E7 -> 296.7 | H7: =D7/C7*100 -> 44.565217 | I7: =B7*0.12 -> 35.604 | K7: 45993 | L7: =109.68+106.98+125.39 -> 342.05 | M7: 146 | N7: 56 | O7: 0 | P7: =L7/M7 -> 2.3428082 | Q7: 0 | R7: =N7/M7*100 -> 38.356164 | S7: =L7*0.1 -> 34.205 | U7: 45963 | AC7: 45963 | AK7: 45963
A8: 45994 | B8: 165.51 | C8: 63 | D8: 33 | E8: 6 | F8: =B8/C8 -> 2.6271429 | G8: =B8/E8 -> 27.585 | H8: =D8/C8*100 -> 52.380952 | I8: =B8*0.12 -> 19.8612 | K8: 45994 | L8: =72.52+72.49+164.71 -> 309.72 | M8: 120 | N8: 61 | O8: 3 | P8: =L8/M8 -> 2.581 | Q8: =L8/O8 -> 103.24 | R8: =N8/M8*100 -> 50.833333 | S8: =L8*0.1 -> 30.972 | U8: 45964 | AC8: 45964 | AK8: 45964
A9: 45995 | B9: 0 | D9: 5 | I9: =B9*0.12 -> 0 | K9: 45995 | L9: =141.69+43.65+184.03 -> 369.37 | M9: 152 | N9: 63 | O9: 5 | P9: =L9/M9 -> 2.4300658 | Q9: =L9/O9 -> 73.874 | R9: =N9/M9*100 -> 41.447368 | S9: =L9*0.1 -> 36.937 | U9: 45965 | AC9: 45965 | AK9: 45965
A10: 45996 | B10: 0 | D10: 2 | E10: 1 | I10: =B10*0.12 -> 0 | K10: 45996 | L10: =179.4+106.68+71.73 -> 357.81 | M10: 95 | N10: 44 | O10: 2 | P10: =L10/M10 -> 3.7664211 | Q10: =L10/O10 -> 178.905 | R10: =N10/M10*100 -> 46.315789 | S10: =L10*0.1 -> 35.781 | U10: 45966 | AC10: 45966 | AK10: 45966
A11: 45997 | B11: 117.95 | C11: 35 | D11: 9 | E11: 3 | F11: =B11/C11 -> 3.37 | G11: =B11/E11 -> 39.316667 | H11: =D11/C11*100 -> 25.714286 | I11: =B11*0.12 -> 14.154 | K11: 45997 | L11: =83.36+ 55.95+ 123.04 -> 262.35 | M11: 109 | N11: 48 | O11: 4 | P11: =L11/M11 -> 2.4068807 | Q11: =L11/O11 -> 65.5875 | R11: =N11/M11*100 -> 44.036697 | S11: =L11*0.1 -> 26.235 | U11: 45967 | AC11: 45967 | AK11: 45967
A12: 45998 | B12: =119.17+ 74.25 -> 193.42 | C12: 68 | D12: 24 | E12: 3 | F12: =B12/C12 -> 2.8444118 | G12: =B12/E12 -> 64.473333 | H12: =D12/C12*100 -> 35.294118 | I12: =B12*0.12 -> 23.2104 | K12: 45998 | L12: =98.64+ 64.95+ 14.47 -> 178.06 | M12: 84 | N12: 37 | O12: 1 | P12: =L12/M12 -> 2.1197619 | Q12: =L12/O12 -> 178.06 | R12: =N12/M12*100 -> 44.047619 | S12: =L12*0.1 -> 17.806 | U12: 45968 | AC12: 45968 | AK12: 45968
A13: 45999 | B13: 14.81 | C13: 1 | D13: 8 | E13: 1 | F13: =B13/C13 -> 14.81 | G13: =B13/E13 -> 14.81 | H13: =D13/C13*100 -> 800 | I13: =B13*0.12 -> 1.7772 | K13: 45999 | L13: =IFERROR(__xludf.DUMMYFUNCTION("SUM(IMPORTRANGE(""1juk7449zs4jpNuI-o5X7XCsKjbIAXWPjQAMji4MmS2g"", ""12/2025!t13:t33""))"),443.38) -> 443.38 | M13: 131 | N13: 50 | O13: 2 | P13: =L13/M13 -> 3.3845802 | Q13: =L13/O13 -> 221.69 | R13: =N13/M13*100 -> 38.167939 | S13: =L13*0.1 -> 44.338 | U13: 45969 | AC13: 45969 | AK13: 45969
A14: 46000 | B14: =28.69+ 105.7+318.89 -> 453.28 | C14: 147 | D14: 57 | E14: 2 | F14: =B14/C14 -> 3.0835374 | G14: =B14/E14 -> 226.64 | H14: =D14/C14*100 -> 38.77551 | I14: =B14*0.12 -> 54.3936 | K14: 46000 | L14: =IFERROR(__xludf.DUMMYFUNCTION("SUM(IMPORTRANGE(""1juk7449zs4jpNuI-o5X7XCsKjbIAXWPjQAMji4MmS2g"", ""12/2025!u13:u33""))"),400.77) -> 400.77 | M14: 140 | N14: 66 | P14: =L14/M14 -> 2.8626429 | R14: =N14/M14*100 -> 47.142857 | S14: =L14*0.1 -> 40.077 | U14: 45970 | AC14: 45970 | AK14: 45970
A15: 46001 | B15: =IFERROR(__xludf.DUMMYFUNCTION("SUM(IMPORTRANGE(""1juk7449zs4jpNuI-o5X7XCsKjbIAXWPjQAMji4MmS2g"", ""12/2025!v5:v12""))"),177.91) -> 177.91 | C15: 52 | D15: 21 | E15: 2 | F15: =B15/C15 -> 3.4213462 | G15: =B15/E15 -> 88.955 | H15: =D15/C15*100 -> 40.384615 | I15: =B15*0.12 -> 21.3492 | K15: 46001 | L15: =IFERROR(__xludf.DUMMYFUNCTION("SUM(IMPORTRANGE(""1juk7449zs4jpNuI-o5X7XCsKjbIAXWPjQAMji4MmS2g"", ""12/2025!v13:v33""))"),270.12) -> 270.12 | M15: 72 | N15: 39 | P15: =L15/M15 -> 3.7516667 | R15: =N15/M15*100 -> 54.166667 | S15: =L15*0.1 -> 27.012 | U15: 45971 | AC15: 45971 | AK15: 45971
A16: 46002 | B16: =IFERROR(__xludf.DUMMYFUNCTION("SUM(IMPORTRANGE(""1juk7449zs4jpNuI-o5X7XCsKjbIAXWPjQAMji4MmS2g"", ""12/2025!w5:w12""))"),207.95999999999998) -> 207.96 | C16: 13 | D16: 9 | E16: 4 | F16: =B16/C16 -> 15.996923 | G16: =B16/E16 -> 51.99 | H16: =D16/C16*100 -> 69.230769 | I16: =B16*0.12 -> 24.9552 | K16: 46002 | L16: =IFERROR(__xludf.DUMMYFUNCTION("SUM(IMPORTRANGE(""1juk7449zs4jpNuI-o5X7XCsKjbIAXWPjQAMji4MmS2g"", ""12/2025!w13:w33""))"),326.03999999999996) -> 326.04 | M16: 107 | N16: 40 | O16: 5 | P16: =L16/M16 -> 3.0471028 | Q16: =L16/O16 -> 65.208 | R16: =N16/M16*100 -> 37.383178 | S16: =L16*0.1 -> 32.604 | U16: 45972 | AC16: 45972 | AK16: 45972
A17: 46003 | B17: =IFERROR(__xludf.DUMMYFUNCTION("SUM(IMPORTRANGE(""1juk7449zs4jpNuI-o5X7XCsKjbIAXWPjQAMji4MmS2g"", ""12/2025!x5:x12""))"),0.0) -> 0 | C17: 1 | D17: 7 | E17: 3 | F17: =B17/C17 -> 0 | G17: =B17/E17 -> 0 | H17: =D17/C17*100 -> 700 | I17: =B17*0.12 -> 0 | K17: 46003 | L17: =IFERROR(__xludf.DUMMYFUNCTION("SUM(IMPORTRANGE(""1juk7449zs4jpNuI-o5X7XCsKjbIAXWPjQAMji4MmS2g"", ""12/2025!x13:x33""))"),416.86) -> 416.86 | M17: 155 | N17: 62 | O17: 1 | P17: =L17/M17 -> 2.6894194 | Q17: =L17/O17 -> 416.86 | R17: =N17/M17*100 -> 40 | S17: =L17*0.1 -> 41.686 | U17: 45973 | AC17: 45973 | AK17: 45973
A18: 46004 | B18: =IFERROR(__xludf.DUMMYFUNCTION("SUM(IMPORTRANGE(""1juk7449zs4jpNuI-o5X7XCsKjbIAXWPjQAMji4MmS2g"", ""12/2025!y5:y12""))"),139.71) -> 139.71 | C18: 16 | D18: 5 | E18: 4 | F18: =B18/C18 -> 8.731875 | G18: =B18/E18 -> 34.9275 | H18: =D18/C18*100 -> 31.25 | I18: =B18*0.12 -> 16.7652 | K18: 46004 | L18: =IFERROR(__xludf.DUMMYFUNCTION("SUM(IMPORTRANGE(""1juk7449zs4jpNuI-o5X7XCsKjbIAXWPjQAMji4MmS2g"", ""12/2025!y13:y33""))"),503.32) -> 503.32 | M18: 159 | N18: 63 | O18: 0 | P18: =L18/M18 -> 3.1655346 | Q18: 0 | R18: =N18/M18*100 -> 39.622642 | S18: =L18*0.1 -> 50.332 | U18: 45974 | AC18: 45974 | AK18: 45974
A19: 46005 | B19: =IFERROR(__xludf.DUMMYFUNCTION("SUM(IMPORTRANGE(""1juk7449zs4jpNuI-o5X7XCsKjbIAXWPjQAMji4MmS2g"", ""12/2025!z5:z12""))"),210.74) -> 210.74 | C19: 31 | D19: 12 | E19: 4 | F19: =B19/C19 -> 6.7980645 | G19: =B19/E19 -> 52.685 | H19: =D19/C19*100 -> 38.709677 | I19: =B19*0.12 -> 25.2888 | K19: 46005 | L19: =IFERROR(__xludf.DUMMYFUNCTION("SUM(IMPORTRANGE(""1juk7449zs4jpNuI-o5X7XCsKjbIAXWPjQAMji4MmS2g"", ""12/2025!z13:z33""))"),425.27000000000004) -> 425.27 | M19: 126 | N19: 58 | O19: 3 | P19: =L19/M19 -> 3.3751587 | Q19: =L19/O19 -> 141.75667 | R19: =N19/M19*100 -> 46.031746 | S19: =L19*0.1 -> 42.527 | U19: 45975 | AC19: 45975 | AK19: 45975
A20: 46006 | B20: =IFERROR(__xludf.DUMMYFUNCTION("SUM(IMPORTRANGE(""1juk7449zs4jpNuI-o5X7XCsKjbIAXWPjQAMji4MmS2g"", ""12/2025!aa5:aa12""))"),234.01) -> 234.01 | C20: 3 | D20: 7 | E20: 1 | F20: =B20/C20 -> 78.003333 | G20: =B20/E20 -> 234.01 | H20: =D20/C20*100 -> 233.33333 | I20: =B20*0.12 -> 28.0812 | K20: 46006 | L20: =IFERROR(__xludf.DUMMYFUNCTION("SUM(IMPORTRANGE(""1juk7449zs4jpNuI-o5X7XCsKjbIAXWPjQAMji4MmS2g"", ""12/2025!aa13:aa33""))"),286.93) -> 286.93 | M20: 115 | N20: 61 | O20: 3 | P20: =L20/M20 -> 2.4950435 | Q20: =L20/O20 -> 95.643333 | R20: =N20/M20*100 -> 53.043478 | S20: =L20*0.1 -> 28.693 | U20: 45976 | AC20: 45976 | AK20: 45976
A21: 46007 | B21: =IFERROR(__xludf.DUMMYFUNCTION("SUM(IMPORTRANGE(""1juk7449zs4jpNuI-o5X7XCsKjbIAXWPjQAMji4MmS2g"", ""12/2025!ab5:ab12""))"),9.31) -> 9.31 | D21: 2 | E21: 1 | G21: =B21/E21 -> 9.31 | I21: =B21*0.12 -> 1.1172 | K21: 46007 | L21: =IFERROR(__xludf.DUMMYFUNCTION("SUM(IMPORTRANGE(""1juk7449zs4jpNuI-o5X7XCsKjbIAXWPjQAMji4MmS2g"", ""12/2025!ab13:ab33""))"),199.04999999999998) -> 199.05 | M21: 72 | N21: 34 | O21: 4 | P21: =L21/M21 -> 2.7645833 | Q21: =L21/O21 -> 49.7625 | R21: =N21/M21*100 -> 47.222222 | S21: =L21*0.1 -> 19.905 | U21: 45977 | AC21: 45977 | AK21: 45977
A22: 46008 | B22: =IFERROR(__xludf.DUMMYFUNCTION("SUM(IMPORTRANGE(""1juk7449zs4jpNuI-o5X7XCsKjbIAXWPjQAMji4MmS2g"", ""12/2025!ac5:ac12""))"),41.72) -> 41.72 | C22: 4 | D22: 6 | F22: =B22/C22 -> 10.43 | H22: =D22/C22*100 -> 150 | I22: =B22*0.12 -> 5.0064 | K22: 46008 | L22: =IFERROR(__xludf.DUMMYFUNCTION("SUM(IMPORTRANGE(""1juk7449zs4jpNuI-o5X7XCsKjbIAXWPjQAMji4MmS2g"", ""12/2025!ac13:ac33""))"),407.08) -> 407.08 | M22: 219 | N22: 102 | O22: 2 | P22: =L22/M22 -> 1.8588128 | Q22: =L22/O22 -> 203.54 | R22: =N22/M22*100 -> 46.575342 | S22: =L22*0.1 -> 40.708 | U22: 45978 | AC22: 45978 | AK22: 45978
A23: 46009 | B23: =IFERROR(__xludf.DUMMYFUNCTION("SUM(IMPORTRANGE(""1juk7449zs4jpNuI-o5X7XCsKjbIAXWPjQAMji4MmS2g"", ""12/2025!ad5:ad12""))"),280.74) -> 280.74 | C23: 65 | D23: 23 | F23: =B23/C23 -> 4.3190769 | H23: =D23/C23*100 -> 35.384615 | I23: =B23*0.12 -> 33.6888 | K23: 46009 | L23: =IFERROR(__xludf.DUMMYFUNCTION("SUM(IMPORTRANGE(""1juk7449zs4jpNuI-o5X7XCsKjbIAXWPjQAMji4MmS2g"", ""12/2025!ad13:ad33""))"),577.87) -> 577.87 | M23: 229 | N23: 89 | O23: 7 | P23: =L23/M23 -> 2.5234498 | Q23: =L23/O23 -> 82.552857 | R23: =N23/M23*100 -> 38.864629 | S23: =L23*0.1 -> 57.787 | U23: 45979 | AC23: 45979 | AK23: 45979
A24: 46010 | B24: =IFERROR(__xludf.DUMMYFUNCTION("SUM(IMPORTRANGE(""1juk7449zs4jpNuI-o5X7XCsKjbIAXWPjQAMji4MmS2g"", ""12/2025!ae5:ae12""))"),236.99) -> 236.99 | C24: 69 | D24: 30 | E24: 3 | F24: =B24/C24 -> 3.4346377 | G24: =B24/E24 -> 78.996667 | H24: =D24/C24*100 -> 43.478261 | I24: =B24*0.12 -> 28.4388 | K24: 46010 | L24: =IFERROR(__xludf.DUMMYFUNCTION("SUM(IMPORTRANGE(""1juk7449zs4jpNuI-o5X7XCsKjbIAXWPjQAMji4MmS2g"", ""12/2025!ae13:ae33""))"),387.09) -> 387.09 | M24: 210 | N24: 77 | O24: 5 | P24: =L24/M24 -> 1.8432857 | Q24: =L24/O24 -> 77.418 | R24: =N24/M24*100 -> 36.666667 | S24: =L24*0.1 -> 38.709 | U24: 45980 | AC24: 45980 | AK24: 45980
A25: 46011 | B25: =IFERROR(__xludf.DUMMYFUNCTION("SUM(IMPORTRANGE(""1juk7449zs4jpNuI-o5X7XCsKjbIAXWPjQAMji4MmS2g"", ""12/2025!af5:af12""))"),114.33) -> 114.33 | C25: 36 | D25: 15 | E25: 2 | F25: =B25/C25 -> 3.1758333 | G25: =B25/E25 -> 57.165 | H25: =D25/C25*100 -> 41.666667 | I25: =B25*0.12 -> 13.7196 | K25: 46011 | L25: =IFERROR(__xludf.DUMMYFUNCTION("SUM(IMPORTRANGE(""1juk7449zs4jpNuI-o5X7XCsKjbIAXWPjQAMji4MmS2g"", ""12/2025!af13:af33""))"),230.79999999999998) -> 230.8 | M25: 165 | N25: 81 | O25: 6 | P25: =L25/M25 -> 1.3987879 | Q25: =L25/O25 -> 38.466667 | R25: =N25/M25*100 -> 49.090909 | S25: =L25*0.1 -> 23.08 | U25: 45981 | AC25: 45981 | AK25: 45981
A26: 46012 | B26: =IFERROR(__xludf.DUMMYFUNCTION("SUM(IMPORTRANGE(""1juk7449zs4jpNuI-o5X7XCsKjbIAXWPjQAMji4MmS2g"", ""12/2025!ag5:ag12""))"),0.0) -> 0 | D26: 4 | E26: 1 | G26: =B26/E26 -> 0 | I26: =B26*0.12 -> 0 | K26: 46012 | L26: =IFERROR(__xludf.DUMMYFUNCTION("SUM(IMPORTRANGE(""1juk7449zs4jpNuI-o5X7XCsKjbIAXWPjQAMji4MmS2g"", ""12/2025!ag13:ag33""))"),132.27) -> 132.27 | M26: 123 | N26: 55 | O26: 2 | P26: =L26/M26 -> 1.0753659 | Q26: =L26/O26 -> 66.135 | R26: =N26/M26*100 -> 44.715447 | S26: =L26*0.1 -> 13.227 | U26: 45982 | AC26: 45982 | AK26: 45982
A27: 46013 | B27: =IFERROR(__xludf.DUMMYFUNCTION("SUM(IMPORTRANGE(""1juk7449zs4jpNuI-o5X7XCsKjbIAXWPjQAMji4MmS2g"", ""12/2025!ah5:ah12""))"),175.18) -> 175.18 | C27: 40 | D27: 16 | E27: 5 | F27: =B27/C27 -> 4.3795 | G27: =B27/E27 -> 35.036 | H27: =D27/C27*100 -> 40 | I27: =B27*0.12 -> 21.0216 | K27: 46013 | L27: =IFERROR(__xludf.DUMMYFUNCTION("SUM(IMPORTRANGE(""1juk7449zs4jpNuI-o5X7XCsKjbIAXWPjQAMji4MmS2g"", ""12/2025!ah13:ah33""))"),363.25) -> 363.25 | M27: 302 | N27: 133 | O27: 2 | P27: =L27/M27 -> 1.2028146 | Q27: =L27/O27 -> 181.625 | R27: =N27/M27*100 -> 44.039735 | S27: =L27*0.1 -> 36.325 | U27: 45983 | AC27: 45983 | AK27: 45983
A28: 46014 | B28: =IFERROR(__xludf.DUMMYFUNCTION("SUM(IMPORTRANGE(""1juk7449zs4jpNuI-o5X7XCsKjbIAXWPjQAMji4MmS2g"", ""12/2025!ai5:ai12""))"),156.3) -> 156.3 | C28: 29 | D28: 16 | E28: 2 | F28: =B28/C28 -> 5.3896552 | G28: =B28/E28 -> 78.15 | H28: =D28/C28*100 -> 55.172414 | I28: =B28*0.12 -> 18.756 | K28: 46014 | L28: =IFERROR(__xludf.DUMMYFUNCTION("SUM(IMPORTRANGE(""1juk7449zs4jpNuI-o5X7XCsKjbIAXWPjQAMji4MmS2g"", ""12/2025!ai13:ai33""))"),370.39) -> 370.39 | M28: 325 | N28: 151 | O28: 4 | P28: =L28/M28 -> 1.1396615 | Q28: =L28/O28 -> 92.5975 | R28: =N28/M28*100 -> 46.461538 | S28: =L28*0.1 -> 37.039 | U28: 45984 | AC28: 45984 | AK28: 45984
A29: 46015 | B29: =IFERROR(__xludf.DUMMYFUNCTION("SUM(IMPORTRANGE(""1juk7449zs4jpNuI-o5X7XCsKjbIAXWPjQAMji4MmS2g"", ""12/2025!aj5:aj12""))"),136.7) -> 136.7 | C29: 45 | D29: 21 | E29: 1 | F29: =B29/C29 -> 3.0377778 | G29: =B29/E29 -> 136.7 | H29: =D29/C29*100 -> 46.666667 | I29: =B29*0.12 -> 16.404 | K29: 46015 | L29: =IFERROR(__xludf.DUMMYFUNCTION("SUM(IMPORTRANGE(""1juk7449zs4jpNuI-o5X7XCsKjbIAXWPjQAMji4MmS2g"", ""12/2025!aj13:aj33""))"),254.23999999999998) -> 254.24 | M29: 249 | N29: 110 | O29: 6 | P29: =L29/M29 -> 1.0210442 | Q29: =L29/O29 -> 42.373333 | R29: =N29/M29*100 -> 44.176707 | S29: =L29*0.1 -> 25.424 | U29: 45985 | AC29: 45985 | AK29: 45985
A30: 46016 | B30: =IFERROR(__xludf.DUMMYFUNCTION("SUM(IMPORTRANGE(""1juk7449zs4jpNuI-o5X7XCsKjbIAXWPjQAMji4MmS2g"", ""12/2025!ak5:ak12""))"),195.7) -> 195.7 | C30: 52 | D30: 23 | E30: 2 | F30: =B30/C30 -> 3.7634615 | G30: =B30/E30 -> 97.85 | H30: =D30/C30*100 -> 44.230769 | I30: =B30*0.12 -> 23.484 | K30: 46016 | L30: =IFERROR(__xludf.DUMMYFUNCTION("SUM(IMPORTRANGE(""1juk7449zs4jpNuI-o5X7XCsKjbIAXWPjQAMji4MmS2g"", ""12/2025!ak13:ak33""))"),308.77) -> 308.77 | M30: 303 | N30: 135 | O30: 5 | P30: =L30/M30 -> 1.0190429 | Q30: =L30/O30 -> 61.754 | R30: =N30/M30*100 -> 44.554455 | S30: =L30*0.1 -> 30.877 | U30: 45986 | AC30: 45986 | AK30: 45986
A31: 46017 | B31: =IFERROR(__xludf.DUMMYFUNCTION("SUM(IMPORTRANGE(""1juk7449zs4jpNuI-o5X7XCsKjbIAXWPjQAMji4MmS2g"", ""12/2025!al5:al12""))"),172.62) -> 172.62 | C31: 65 | D31: 17 | E31: 12 | F31: =B31/C31 -> 2.6556923 | G31: =B31/E31 -> 14.385 | H31: =D31/C31*100 -> 26.153846 | I31: =B31*0.12 -> 20.7144 | K31: 46017 | L31: =IFERROR(__xludf.DUMMYFUNCTION("SUM(IMPORTRANGE(""1juk7449zs4jpNuI-o5X7XCsKjbIAXWPjQAMji4MmS2g"", ""12/2025!al13:al33""))"),222.10999999999999) -> 222.11 | M31: 247 | N31: 110 | O31: 3 | P31: =L31/M31 -> 0.89923077 | Q31: =L31/O31 -> 74.036667 | R31: =N31/M31*100 -> 44.534413 | S31: =L31*0.1 -> 22.211 | U31: 45987 | AC31: 45987 | AK31: 45987
A32: 46018 | B32: =IFERROR(__xludf.DUMMYFUNCTION("SUM(IMPORTRANGE(""1juk7449zs4jpNuI-o5X7XCsKjbIAXWPjQAMji4MmS2g"", ""12/2025!am5:am12""))"),99.97) -> 99.97 | C32: 33 | D32: 19 | E32: 1 | F32: =B32/C32 -> 3.0293939 | G32: =B32/E32 -> 99.97 | H32: =D32/C32*100 -> 57.575758 | I32: =B32*0.12 -> 11.9964 | K32: 46018 | L32: =IFERROR(__xludf.DUMMYFUNCTION("SUM(IMPORTRANGE(""1juk7449zs4jpNuI-o5X7XCsKjbIAXWPjQAMji4MmS2g"", ""12/2025!am13:am33""))"),300.30999999999995) -> 300.31 | M32: 299 | N32: 145 | O32: 9 | P32: =L32/M32 -> 1.0043813 | Q32: =L32/O32 -> 33.367778 | R32: =N32/M32*100 -> 48.494983 | S32: =L32*0.1 -> 30.031 | U32: 45988 | AC32: 45988 | AK32: 45988
A33: 46019 | B33: =IFERROR(__xludf.DUMMYFUNCTION("SUM(IMPORTRANGE(""1juk7449zs4jpNuI-o5X7XCsKjbIAXWPjQAMji4MmS2g"", ""12/2025!an5:an12""))"),0.0) -> 0 | I33: =B33*0.12 -> 0 | K33: 46019 | L33: =IFERROR(__xludf.DUMMYFUNCTION("SUM(IMPORTRANGE(""1juk7449zs4jpNuI-o5X7XCsKjbIAXWPjQAMji4MmS2g"", ""12/2025!an13:an33""))"),321.34000000000003) -> 321.34 | M33: 352 | N33: 166 | O33: 7 | P33: =L33/M33 -> 0.91289773 | Q33: =L33/O33 -> 45.905714 | R33: =N33/M33*100 -> 47.159091 | S33: =L33*0.1 -> 32.134 | U33: 45989 | AC33: 45989 | AK33: 45989
A34: 46020 | B34: =IFERROR(__xludf.DUMMYFUNCTION("SUM(IMPORTRANGE(""1juk7449zs4jpNuI-o5X7XCsKjbIAXWPjQAMji4MmS2g"", ""12/2025!ao5:ao12""))"),0.0) -> 0 | I34: =B34*0.12 -> 0 | K34: 46020 | L34: =IFERROR(__xludf.DUMMYFUNCTION("SUM(IMPORTRANGE(""1juk7449zs4jpNuI-o5X7XCsKjbIAXWPjQAMji4MmS2g"", ""12/2025!ao13:ao33""))"),285.61) -> 285.61 | M34: 299 | N34: 132 | O34: 4 | P34: =L34/M34 -> 0.95521739 | Q34: =L34/O34 -> 71.4025 | R34: =N34/M34*100 -> 44.147157 | S34: =L34*0.1 -> 28.561 | U34: 45990 | AC34: 45990 | AK34: 45990
A35: 46021 | B35: =IFERROR(__xludf.DUMMYFUNCTION("SUM(IMPORTRANGE(""1juk7449zs4jpNuI-o5X7XCsKjbIAXWPjQAMji4MmS2g"", ""12/2025!ap5:ap12""))"),0.0) -> 0 | I35: =B35*0.12 -> 0 | K35: 46021 | L35: =IFERROR(__xludf.DUMMYFUNCTION("SUM(IMPORTRANGE(""1juk7449zs4jpNuI-o5X7XCsKjbIAXWPjQAMji4MmS2g"", ""12/2025!ap13:ap33""))"),190.20000000000002) -> 190.2 | M35: 194 | N35: 94 | O35: 2 | P35: =L35/M35 -> 0.98041237 | Q35: =L35/O35 -> 95.1 | R35: =N35/M35*100 -> 48.453608 | S35: =L35*0.1 -> 19.02 | U35: 45991 | AC35: 45991 | AK35: 45991
A36: 46022 | B36: =IFERROR(__xludf.DUMMYFUNCTION("SUM(IMPORTRANGE(""1juk7449zs4jpNuI-o5X7XCsKjbIAXWPjQAMji4MmS2g"", ""12/2025!aq5:aq12""))"),0.0) -> 0 | I36: =B36*0.12 -> 0 | K36: 46022 | L36: =IFERROR(__xludf.DUMMYFUNCTION("SUM(IMPORTRANGE(""1juk7449zs4jpNuI-o5X7XCsKjbIAXWPjQAMji4MmS2g"", ""12/2025!aq13:aq33""))"),0.0) -> 0 | M36: 1 | N36: 11 | O36: 2 | P36: =L36/M36 -> 0 | Q36: =L36/O36 -> 0 | R36: =N36/M36*100 -> 1100 | S36: =L36*0.1 -> 0
A37: ИТОГО: | B37: =SUM(B6:B35) -> 4137.14 | C37: =SUM(C6:C35) -> 1056 | D37: =SUM(D6:D35) -> 478 | E37: =SUM(E6:E35) -> 71 | F37: =B37/C37 -> 3.9177462 | G37: =B37/E37 -> 58.269577 | H37: =D37/C37*100 -> 45.265152 | I37: =B37*0.12 -> 496.4568 | K37: ИТОГО: | L37: =SUM(L6:L35) -> 9693.86 | M37: =SUM(M6:M36) -> 5381 | N37: =SUM(N6:N36) -> 2414 | O37: =SUM(O6:O36) -> 103 | P37: =L37/M37 -> 1.8014979 | Q37: =L37/O37 -> 94.115146 | R37: =N37/M37*100 -> 44.86155 | S37: =SUM(S6:S36) -> 969.386 | U37: ИТОГО: | V37: =SUM(V6:V35) -> 0 | W37: =SUM(W6:W35) -> 0 | X37: =SUM(X6:X35) -> 0 | Y37: =SUM(Y6:Y35) -> 0 | Z37: =SUM(Z6:Z35) -> 0 | AA37: =SUM(AA6:AA35) -> 0 | AC37: ИТОГО: | AD37: =SUM(AD6:AD35) -> 0 | AE37: =SUM(AE6:AE35) -> 0 | AF37: =SUM(AF6:AF35) -> 0 | AG37: =SUM(AG6:AG35) -> 0 | AH37: =SUM(AH6:AH35) -> 0 | AI37: =SUM(AI6:AI35) -> 0 | AK37: ИТОГО: | AL37: =SUM(AL6:AL35) -> 0 | AM37: =SUM(AM6:AM35) -> 0 | AN37: =SUM(AN6:AN35) -> 0 | AO37: =SUM(AO6:AO35) -> 0 | AP37: =SUM(AP6:AP35) -> 0 | AQ37: =SUM(AQ6:AQ35) -> 0

Sheet Италия(декабрь)
A3: Cabrera (итальянец) | K3: Cabrera2 | U3: Moms manager (сеньор)
A4: 759443220489882 | K4: 1.8078903e+15 | U4: FBM
A5: Дата | B5: Общий спенд | C5: Подписки | D5: Диалоги | E5: ФД | F5: Цена подписки | G5: Цена ФД | H5: Конверсия % | I5: ЗП | K5: Дата | L5: Общий спенд | M5: Подписки | N5: Диалоги | O5: ФД | P5: Цена подписки | Q5: Конверсия % | R5: Цена ФД | S5: ЗП | U5: Дата | V5: Общий спенд | W5: Подписки | X5: Диалоги | Y5: ФД | Z5: Цена подписки | AA5: Конверсия % | AB5: Цена ФД
A6: 45992 | B6: =152.98+15.57+82.88 -> 251.43 | C6: 38 | D6: 23 | E6: 1 | F6: =B6/C6 -> 6.6165789 | G6: =B6/E6 -> 251.43 | H6: =D6/C6*100 -> 60.526316 | I6: =B6*0.1 -> 25.143 | K6: 45992 | U6: 45962
A7: 45993 | B7: =109.68+106.98+125.39 -> 342.05 | C7: 53 | D7: 21 | E7: 2 | F7: =B7/C7 -> 6.4537736 | G7: =B7/E7 -> 171.025 | H7: =D7/C7*100 -> 39.622642 | I7: =B7*0.1 -> 34.205 | K7: 45993 | U7: 45963
A8: 45994 | B8: =72.52+72.49+164.71 -> 309.72 | C8: 68 | D8: 38 | E8: 1 | F8: =B8/C8 -> 4.5547059 | G8: =B8/E8 -> 309.72 | H8: =D8/C8*100 -> 55.882353 | I8: =B8*0.1 -> 30.972 | K8: 45994 | U8: 45964
A9: 45995 | B9: =141.69+43.65+184.03 -> 369.37 | C9: 72 | D9: 42 | I9: =B9*0.1 -> 36.937 | K9: 45995 | U9: 45965
A10: 45996 | B10: =179.4+106.68+71.73 -> 357.81 | C10: 65 | D10: 41 | E10: 2 | I10: =B10*0.1 -> 35.781 | K10: 45996 | U10: 45966
A11: 45997 | B11: =83.36+ 55.95+ 123.04 -> 262.35 | C11: 132 | D11: 66 | E11: 1 | F11: =B11/C11 -> 1.9875 | G11: =B11/E11 -> 262.35 | H11: =D11/C11*100 -> 50 | I11: =B11*0.1 -> 26.235 | K11: 45997 | U11: 45967
A12: 45998 | C12: 147 | D12: 100 | F12: =B12/C12 -> 0 | H12: =D12/C12*100 -> 68.027211 | I12: =B12*0.1 -> 0 | K12: 45998 | U12: 45968
A13: 45999 | C13: 79 | D13: 47 | E13: 3 | F13: =B13/C13 -> 0 | G13: =B13/E13 -> 0 | H13: =D13/C13*100 -> 59.493671 | I13: =B13*0.1 -> 0 | K13: 45999 | U13: 45969
A14: 46000 | B14: =IFERROR(__xludf.DUMMYFUNCTION("TRANSPOSE(IMPORTRANGE(""1mLYrOR0lYe8tWsFhslUhEyhEhRjCr_h4lljPfqzhMvE"", ""DailySpend_Dec25!P5:al5""))"),276.16) -> 276.16 | C14: 85 | D14: 51 | E14: 3 | F14: =B14/C14 -> 3.2489412 | G14: =B14/E14 -> 92.053333 | H14: =D14/C14*100 -> 60 | I14: =B14*0.1 -> 27.616 | K14: 46000 | U14: 45970
A15: 46001 | B15: =IFERROR(__xludf.DUMMYFUNCTION("""COMPUTED_VALUE"""),217.9) -> 217.9 | C15: 61 | D15: 35 | E15: 4 | F15: =B15/C15 -> 3.5721311 | G15: =B15/E15 -> 54.475 | H15: =D15/C15*100 -> 57.377049 | I15: =B15*0.1 -> 21.79 | K15: 46001 | U15: 45971
A16: 46002 | B16: =IFERROR(__xludf.DUMMYFUNCTION("""COMPUTED_VALUE"""),243.71) -> 243.71 | C16: 91 | D16: 47 | E16: 1 | F16: =B16/C16 -> 2.6781319 | G16: =B16/E16 -> 243.71 | H16: =D16/C16*100 -> 51.648352 | I16: =B16*0.1 -> 24.371 | K16: 46002 | U16: 45972
A17: 46003 | B17: =IFERROR(__xludf.DUMMYFUNCTION("""COMPUTED_VALUE"""),299.74) -> 299.74 | C17: 104 | D17: 61 | E17: 3 | F17: =B17/C17 -> 2.8821154 | G17: =B17/E17 -> 99.913333 | H17: =D17/C17*100 -> 58.653846 | I17: =B17*0.1 -> 29.974 | K17: 46003 | U17: 45973
A18: 46004 | B18: =IFERROR(__xludf.DUMMYFUNCTION("""COMPUTED_VALUE"""),292.76) -> 292.76 | C18: 61 | D18: 41 | E18: 4 | F18: =B18/C18 -> 4.7993443 | G18: =B18/E18 -> 73.19 | H18: =D18/C18*100 -> 67.213115 | I18: =B18*0.1 -> 29.276 | K18: 46004 | U18: 45974
A19: 46005 | B19: =IFERROR(__xludf.DUMMYFUNCTION("""COMPUTED_VALUE"""),349.75) -> 349.75 | C19: 123 | D19: 68 | E19: 1 | F19: =B19/C19 -> 2.8434959 | G19: =B19/E19 -> 349.75 | H19: =D19/C19*100 -> 55.284553 | I19: =B19*0.1 -> 34.975 | K19: 46005 | U19: 45975
A20: 46006 | B20: =IFERROR(__xludf.DUMMYFUNCTION("""COMPUTED_VALUE"""),433.26) -> 433.26 | C20: 121 | D20: 54 | E20: 4 | F20: =B20/C20 -> 3.5806612 | G20: =B20/E20 -> 108.315 | H20: =D20/C20*100 -> 44.628099 | I20: =B20*0.1 -> 43.326 | K20: 46006 | U20: 45976
A21: 46007 | B21: =IFERROR(__xludf.DUMMYFUNCTION("""COMPUTED_VALUE"""),324.19) -> 324.19 | C21: 90 | D21: 50 | E21: 3 | F21: =B21/C21 -> 3.6021111 | G21: =B21/E21 -> 108.06333 | H21: =D21/C21*100 -> 55.555556 | I21: =B21*0.1 -> 32.419 | K21: 46007 | U21: 45977
A22: 46008 | B22: =IFERROR(__xludf.DUMMYFUNCTION("""COMPUTED_VALUE"""),341.67) -> 341.67 | C22: 95 | D22: 47 | E22: 2 | F22: =B22/C22 -> 3.5965263 | G22: =B22/E22 -> 170.835 | H22: =D22/C22*100 -> 49.473684 | I22: =B22*0.1 -> 34.167 | K22: 46008 | U22: 45978
A23: 46009 | B23: =IFERROR(__xludf.DUMMYFUNCTION("""COMPUTED_VALUE"""),344.59) -> 344.59 | C23: 76 | D23: 47 | E23: 1 | F23: =B23/C23 -> 4.5340789 | G23: =B23/E23 -> 344.59 | H23: =D23/C23*100 -> 61.842105 | I23: =B23*0.1 -> 34.459 | K23: 46009 | U23: 45979
A24: 46010 | B24: =IFERROR(__xludf.DUMMYFUNCTION("""COMPUTED_VALUE"""),375.58) -> 375.58 | C24: 75 | D24: 45 | E24: 1 | F24: =B24/C24 -> 5.0077333 | G24: =B24/E24 -> 375.58 | H24: =D24/C24*100 -> 60 | I24: =B24*0.1 -> 37.558 | K24: 46010 | U24: 45980
A25: 46011 | B25: =IFERROR(__xludf.DUMMYFUNCTION("""COMPUTED_VALUE"""),238.29) -> 238.29 | C25: =65+40 -> 105 | D25: =36+17 -> 53 | E25: 1 | F25: =B25/C25 -> 2.2694286 | G25: =B25/E25 -> 238.29 | H25: =D25/C25*100 -> 50.47619 | I25: =B25*0.1 -> 23.829 | K25: 46011 | U25: 45981
A26: 46012 | B26: =IFERROR(__xludf.DUMMYFUNCTION("""COMPUTED_VALUE"""),366.72) -> 366.72 | C26: 98 | D26: 54 | E26: 2 | F26: =B26/C26 -> 3.7420408 | G26: =B26/E26 -> 183.36 | H26: =D26/C26*100 -> 55.102041 | I26: =B26*0.1 -> 36.672 | K26: 46012 | U26: 45982
A27: 46013 | B27: =IFERROR(__xludf.DUMMYFUNCTION("""COMPUTED_VALUE"""),344.45) -> 344.45 | C27: 106 | D27: 48 | E27: 4 | F27: =B27/C27 -> 3.2495283 | G27: =B27/E27 -> 86.1125 | H27: =D27/C27*100 -> 45.283019 | I27: =B27*0.1 -> 34.445 | K27: 46013 | U27: 45983
A28: 46014 | B28: =IFERROR(__xludf.DUMMYFUNCTION("""COMPUTED_VALUE"""),307.04) -> 307.04 | C28: 73 | D28: 33 | E28: 3 | F28: =B28/C28 -> 4.2060274 | G28: =B28/E28 -> 102.34667 | H28: =D28/C28*100 -> 45.205479 | I28: =B28*0.1 -> 30.704 | K28: 46014 | U28: 45984
A29: 46015 | B29: =IFERROR(__xludf.DUMMYFUNCTION("""COMPUTED_VALUE"""),242.77) -> 242.77 | C29: 54 | D29: 26 | E29: 3 | F29: =B29/C29 -> 4.4957407 | G29: =B29/E29 -> 80.923333 | H29: =D29/C29*100 -> 48.148148 | I29: =B29*0.1 -> 24.277 | K29: 46015 | U29: 45985
A30: 46016 | B30: =IFERROR(__xludf.DUMMYFUNCTION("""COMPUTED_VALUE"""),318.26) -> 318.26 | C30: 76 | D30: 36 | E30: 1 | F30: =B30/C30 -> 4.1876316 | G30: =B30/E30 -> 318.26 | H30: =D30/C30*100 -> 47.368421 | I30: =B30*0.1 -> 31.826 | K30: 46016 | U30: 45986
A31: 46017 | B31: =IFERROR(__xludf.DUMMYFUNCTION("""COMPUTED_VALUE"""),26.14) -> 26.14 | C31: 4 | D31: 4 | E31: 1 | F31: =B31/C31 -> 6.535 | G31: =B31/E31 -> 26.14 | H31: =D31/C31*100 -> 100 | I31: =B31*0.1 -> 2.614 | K31: 46017 | U31: 45987
A32: 46018 | B32: =IFERROR(__xludf.DUMMYFUNCTION("""COMPUTED_VALUE"""),"") | C32: 0 | D32: 1 | E32: 0 | F32: 0 | G32: 0 | H32: 0 | I32: =B32*0.1 -> 0 | K32: 46018 | U32: 45988
A33: 46019 | B33: =IFERROR(__xludf.DUMMYFUNCTION("""COMPUTED_VALUE"""),169.44) -> 169.44 | C33: 62 | D33: 33 | E33: 0 | F33: =B33/C33 -> 2.7329032 | G33: 0 | H33: =D33/C33*100 -> 53.225806 | I33: =B33*0.1 -> 16.944 | K33: 46019 | U33: 45989
A34: 46020 | B34: =IFERROR(__xludf.DUMMYFUNCTION("""COMPUTED_VALUE"""),"") | C34: 0 | D34: 3 | E34: 1 | F34: 0 | G34: =B34/E34 -> 0 | H34: 0 | I34: =B34*0.1 -> 0 | K34: 46020 | U34: 45990
A35: 46021 | B35: =IFERROR(__xludf.DUMMYFUNCTION("""COMPUTED_VALUE"""),"") | C35: 0 | D35: 2 | E35: 1 | F35: 0 | G35: =B35/E35 -> 0 | H35: 0 | I35: =B35*0.1 -> 0 | K35: 46021 | U35: 45991
A36: 46022 | B36: =IFERROR(__xludf.DUMMYFUNCTION("""COMPUTED_VALUE"""),"") | C36: 0 | D36: 2 | E36: 0 | F36: 0 | G36: 0 | H36: 0 | I36: =B36*0.1 -> 0 | K36: 46022
A38: ИТОГО: | B38: =SUM(B6:B36) -> 7405.15 | C38: =SUM(C6:C36) -> 2214 | D38: =SUM(D6:D36) -> 1219 | E38: =SUM(E6:E36) -> 54 | F38: =B38/C38 -> 3.3446929 | G38: =B38/E38 -> 137.13241 | H38: =D38/C38*100 -> 55.058717 | I38: =B38*0.1 -> 740.515 | K38: ИТОГО: | L38: =SUM(L6:L36) -> 0 | M38: =SUM(M6:M36) -> 0 | N38: =SUM(N6:N36) -> 0 | O38: =SUM(O6:O36) -> 0 | P38: =L38/M38 -> #DIV/0! | Q38: =L38/O38 -> #DIV/0! | R38: =N38/M38*100 -> #DIV/0! | S38: =L38*0.1 -> 0

Sheet Недели
A1: Corie | K1: Corie
A2: Перу | K2: Перу
A3: Дата | B3: Общий спенд | C3: Подписки | D3: Диалоги | E3: ФД | F3: Цена подписки | G3: Конверсия % | H3: Цена ФД | I3: ЗП | K3: Дата | L3: Общий спенд | M3: Подписки | N3: Диалоги | O3: ФД | P3: Цена подписки | Q3: Конверсия % | R3: Цена ФД | S3: ЗП
A4: 01.12-07.12 | B4: =SUM('Перу(декабрь)'!L6 :'Перу(декабрь)'!L12) -> 2070.79 | C4: =SUM('Перу(декабрь)'!M6 :'Перу(декабрь)'!M12) -> 787 | D4: =SUM('Перу(декабрь)'!N6 :'Перу(декабрь)'!N12) -> 350 | E4: =SUM('Перу(декабрь)'!O6 :'Перу(декабрь)'!O12) -> 19 | F4: =(B4/C4) -> 2.6312452 | G4: =(D4/C4*100) -> 44.472681 | H4: =(B4/E4) -> 108.98895 | I4: =B4*0.1 -> 207.079 | K4: 01.01-11.01 | L4: =SUM('Перу(январь)'!M6 :'Перу(январь)'!M16) -> 3464.32 | M4: =SUM('Перу(январь)'!N6 :'Перу(январь)'!N16) -> 3488 | N4: =SUM('Перу(январь)'!O6 :'Перу(январь)'!O16) -> 1835 | O4: =SUM('Перу(январь)'!P6 :'Перу(январь)'!P16) -> 73 | P4: =IFERROR(L4/M4,0) -> 0.99321101 | Q4: =IFERROR(N4/M4,0) -> 0.52608945 | R4: =IFERROR(L4/O4,0) -> 47.456438 | S4: =L4*0.1 -> 346.432
A5: 08.12-14.12 | B5: =SUM('Перу(декабрь)'!L13 :'Перу(декабрь)'!L19) -> 2785.76 | C5: =SUM('Перу(декабрь)'!M13 :'Перу(декабрь)'!M19) -> 890 | D5: =SUM('Перу(декабрь)'!N13 :'Перу(декабрь)'!N19) -> 378 | E5: =SUM('Перу(декабрь)'!O13 :'Перу(декабрь)'!O19) -> 11 | F5: =(B5/C5) -> 3.1300674 | G5: =(D5/C5*100) -> 42.47191 | H5: =(B5/E5) -> 253.25091 | I5: =B5*0.1 -> 278.576 | K5: 12.01-18.01 | L5: =SUM('Перу(январь)'!M17 :'Перу(январь)'!M23) -> 3004.44 | M5: =SUM('Перу(январь)'!N17 :'Перу(январь)'!N23) -> 1112 | N5: =SUM('Перу(январь)'!O17 :'Перу(январь)'!O23) -> 504 | O5: =SUM('Перу(январь)'!P17 :'Перу(январь)'!P23) -> 15 | P5: =IFERROR(L5/M5,0) -> 2.7018345 | Q5: =IFERROR(N5/M5,0) -> 0.45323741 | R5: =IFERROR(L5/O5,0) -> 200.296 | S5: =L5*0.1 -> 300.444
